2024-02-07 13:47:21,200 INFO An Info
2024-02-07 13:47:21,201 ERROR An Error
2024-02-07 13:47:21,478 INFO Start polling
2024-02-07 13:47:21,554 INFO Run polling for bot @foodfindbot id=6523255231 - 'Фишт'
2024-02-07 14:20:30,259 INFO Update id=774151609 is handled. Duration 60799 ms by bot id=6523255231
2024-02-07 16:06:24,498 INFO Update id=774151610 is handled. Duration 771 ms by bot id=6523255231
2024-02-07 16:06:28,969 INFO Update id=774151611 is handled. Duration 320 ms by bot id=6523255231
2024-02-07 16:06:34,849 INFO Update id=774151612 is handled. Duration 224 ms by bot id=6523255231
2024-02-07 16:06:36,555 INFO Update id=774151613 is handled. Duration 178 ms by bot id=6523255231
2024-02-07 16:06:43,302 INFO Update id=774151614 is handled. Duration 129 ms by bot id=6523255231
2024-02-07 16:06:46,608 INFO Update id=774151615 is handled. Duration 137 ms by bot id=6523255231
2024-02-08 04:02:02,662 ERROR Failed to fetch updates - TelegramNetworkError: HTTP Client says - ServerDisconnectedError: Server disconnected
2024-02-08 04:02:02,662 WARNING Sleep for 1.000000 seconds and try again... (tryings = 0, bot id = 6523255231)
2024-02-08 04:02:14,163 INFO Connection established (tryings = 1, bot id = 6523255231)
2024-02-08 09:34:20,128 INFO Update id=774151616 is handled. Duration 2026 ms by bot id=6523255231
2024-02-08 09:34:45,540 INFO Update id=774151617 is handled. Duration 1802 ms by bot id=6523255231
2024-02-08 09:37:26,306 INFO Update id=774151618 is handled. Duration 2038 ms by bot id=6523255231
2024-02-08 12:24:16,930 ERROR Failed to fetch updates - TelegramNetworkError: HTTP Client says - Request timeout error
2024-02-08 12:24:16,930 WARNING Sleep for 1.000000 seconds and try again... (tryings = 0, bot id = 6523255231)
2024-02-08 12:24:28,220 INFO Connection established (tryings = 1, bot id = 6523255231)
2024-02-08 15:52:55,413 ERROR Failed to fetch updates - TelegramNetworkError: HTTP Client says - ServerDisconnectedError: Server disconnected
2024-02-08 15:52:55,413 WARNING Sleep for 1.000000 seconds and try again... (tryings = 0, bot id = 6523255231)
2024-02-08 15:53:06,684 INFO Connection established (tryings = 1, bot id = 6523255231)
2024-02-08 15:53:06,685 ERROR Failed to fetch updates - TelegramNetworkError: HTTP Client says - ServerDisconnectedError: Server disconnected
2024-02-08 15:53:06,685 WARNING Sleep for 1.000000 seconds and try again... (tryings = 0, bot id = 6523255231)
2024-02-08 15:53:17,906 INFO Connection established (tryings = 1, bot id = 6523255231)
2024-02-08 15:54:28,451 ERROR Failed to fetch updates - TelegramNetworkError: HTTP Client says - ServerDisconnectedError: Server disconnected
2024-02-08 15:54:28,451 WARNING Sleep for 1.000000 seconds and try again... (tryings = 0, bot id = 6523255231)
2024-02-08 15:54:39,754 INFO Connection established (tryings = 1, bot id = 6523255231)
2024-02-08 15:55:50,386 ERROR Failed to fetch updates - TelegramNetworkError: HTTP Client says - ServerDisconnectedError: Server disconnected
2024-02-08 15:55:50,386 WARNING Sleep for 1.000000 seconds and try again... (tryings = 0, bot id = 6523255231)
2024-02-08 15:56:01,731 INFO Connection established (tryings = 1, bot id = 6523255231)
2024-02-08 15:56:31,961 ERROR Failed to fetch updates - TelegramNetworkError: HTTP Client says - ServerDisconnectedError: Server disconnected
2024-02-08 15:56:31,961 WARNING Sleep for 1.000000 seconds and try again... (tryings = 0, bot id = 6523255231)
2024-02-08 15:56:43,218 INFO Connection established (tryings = 1, bot id = 6523255231)
2024-02-08 17:04:48,189 ERROR Failed to fetch updates - TelegramNetworkError: HTTP Client says - ClientConnectorError: Cannot connect to host api.telegram.org:443 ssl:default [Network is unreachable]
2024-02-08 17:04:48,189 WARNING Sleep for 1.000000 seconds and try again... (tryings = 0, bot id = 6523255231)
2024-02-08 17:04:59,451 INFO Connection established (tryings = 1, bot id = 6523255231)
2024-02-09 04:02:03,192 ERROR Failed to fetch updates - TelegramNetworkError: HTTP Client says - ServerDisconnectedError: Server disconnected
2024-02-09 04:02:03,192 WARNING Sleep for 1.000000 seconds and try again... (tryings = 0, bot id = 6523255231)
2024-02-09 04:02:14,461 INFO Connection established (tryings = 1, bot id = 6523255231)
2024-02-09 07:34:28,269 INFO Update id=774151619 is handled. Duration 2044 ms by bot id=6523255231
2024-02-09 07:35:10,812 INFO Update id=774151620 is handled. Duration 1774 ms by bot id=6523255231
2024-02-09 07:36:45,391 INFO Update id=774151621 is handled. Duration 1758 ms by bot id=6523255231
2024-02-09 07:38:51,331 INFO Update id=774151622 is handled. Duration 1700 ms by bot id=6523255231
2024-02-09 07:38:58,738 INFO Update id=774151623 is handled. Duration 1475 ms by bot id=6523255231
2024-02-09 07:39:24,315 INFO Update id=774151624 is handled. Duration 1893 ms by bot id=6523255231
2024-02-09 07:45:08,800 INFO Update id=774151625 is handled. Duration 1898 ms by bot id=6523255231
2024-02-09 07:45:28,250 INFO Update id=774151626 is handled. Duration 3472 ms by bot id=6523255231
2024-02-09 07:48:09,891 INFO Update id=774151627 is handled. Duration 3231 ms by bot id=6523255231
2024-02-09 09:41:06,899 INFO Update id=774151628 is not handled. Duration 3350 ms by bot id=6523255231
2024-02-09 09:41:06,899 ERROR Cause exception while process update id=774151628 by bot id=6523255231
IndexError: list index out of range
Traceback (most recent call last):
  File "/home/user/bot/lcbot/venv/lib/python3.11/site-packages/aiogram/dispatcher/dispatcher.py", line 308, in _process_update
    response = await self.feed_update(bot, update, **kwargs)
               ^^^^^^^^^^^^^^^^^^^^^^^^^^^^^^^^^^^^^^^^^^^^^
  File "/home/user/bot/lcbot/venv/lib/python3.11/site-packages/aiogram/dispatcher/dispatcher.py", line 157, in feed_update
    response = await self.update.wrap_outer_middleware(
               ^^^^^^^^^^^^^^^^^^^^^^^^^^^^^^^^^^^^^^^^
  File "/home/user/bot/lcbot/venv/lib/python3.11/site-packages/aiogram/dispatcher/middlewares/error.py", line 25, in __call__
    return await handler(event, data)
           ^^^^^^^^^^^^^^^^^^^^^^^^^^
  File "/home/user/bot/lcbot/venv/lib/python3.11/site-packages/aiogram/dispatcher/middlewares/user_context.py", line 27, in __call__
    return await handler(event, data)
           ^^^^^^^^^^^^^^^^^^^^^^^^^^
  File "/home/user/bot/lcbot/venv/lib/python3.11/site-packages/aiogram/fsm/middleware.py", line 41, in __call__
    return await handler(event, data)
           ^^^^^^^^^^^^^^^^^^^^^^^^^^
  File "/home/user/bot/lcbot/venv/lib/python3.11/site-packages/aiogram/dispatcher/event/telegram.py", line 120, in trigger
    return await wrapped_inner(event, kwargs)
           ^^^^^^^^^^^^^^^^^^^^^^^^^^^^^^^^^^
  File "/home/user/bot/lcbot/venv/lib/python3.11/site-packages/aiogram/dispatcher/event/handler.py", line 42, in call
    return await wrapped()
           ^^^^^^^^^^^^^^^
  File "/home/user/bot/lcbot/venv/lib/python3.11/site-packages/aiogram/dispatcher/dispatcher.py", line 275, in _listen_update
    return await self.propagate_event(update_type=update_type, event=event, **kwargs)
           ^^^^^^^^^^^^^^^^^^^^^^^^^^^^^^^^^^^^^^^^^^^^^^^^^^^^^^^^^^^^^^^^^^^^^^^^^^
  File "/home/user/bot/lcbot/venv/lib/python3.11/site-packages/aiogram/dispatcher/router.py", line 116, in propagate_event
    return await observer.wrap_outer_middleware(_wrapped, event=event, data=kwargs)
           ^^^^^^^^^^^^^^^^^^^^^^^^^^^^^^^^^^^^^^^^^^^^^^^^^^^^^^^^^^^^^^^^^^^^^^^^
  File "/home/user/bot/lcbot/venv/lib/python3.11/site-packages/aiogram/dispatcher/router.py", line 111, in _wrapped
    return await self._propagate_event(
           ^^^^^^^^^^^^^^^^^^^^^^^^^^^^
  File "/home/user/bot/lcbot/venv/lib/python3.11/site-packages/aiogram/dispatcher/router.py", line 136, in _propagate_event
    response = await observer.trigger(event, **kwargs)
               ^^^^^^^^^^^^^^^^^^^^^^^^^^^^^^^^^^^^^^^
  File "/home/user/bot/lcbot/venv/lib/python3.11/site-packages/aiogram/dispatcher/event/telegram.py", line 120, in trigger
    return await wrapped_inner(event, kwargs)
           ^^^^^^^^^^^^^^^^^^^^^^^^^^^^^^^^^^
  File "/home/user/bot/lcbot/venv/lib/python3.11/site-packages/aiogram/dispatcher/event/handler.py", line 42, in call
    return await wrapped()
           ^^^^^^^^^^^^^^^
  File "/home/user/bot/lcbot/bot.py", line 110, in check_imei
    device = imei_device[1].split(": ")[1] + " " + imei_device[3].split(": ")[1]
             ~~~~~~~~~~~^^^
IndexError: list index out of range
2024-02-09 10:42:30,085 INFO Update id=774151629 is not handled. Duration 2564 ms by bot id=6523255231
2024-02-09 10:42:30,085 ERROR Cause exception while process update id=774151629 by bot id=6523255231
IndexError: list index out of range
Traceback (most recent call last):
  File "/home/user/bot/lcbot/venv/lib/python3.11/site-packages/aiogram/dispatcher/dispatcher.py", line 308, in _process_update
    response = await self.feed_update(bot, update, **kwargs)
               ^^^^^^^^^^^^^^^^^^^^^^^^^^^^^^^^^^^^^^^^^^^^^
  File "/home/user/bot/lcbot/venv/lib/python3.11/site-packages/aiogram/dispatcher/dispatcher.py", line 157, in feed_update
    response = await self.update.wrap_outer_middleware(
               ^^^^^^^^^^^^^^^^^^^^^^^^^^^^^^^^^^^^^^^^
  File "/home/user/bot/lcbot/venv/lib/python3.11/site-packages/aiogram/dispatcher/middlewares/error.py", line 25, in __call__
    return await handler(event, data)
           ^^^^^^^^^^^^^^^^^^^^^^^^^^
  File "/home/user/bot/lcbot/venv/lib/python3.11/site-packages/aiogram/dispatcher/middlewares/user_context.py", line 27, in __call__
    return await handler(event, data)
           ^^^^^^^^^^^^^^^^^^^^^^^^^^
  File "/home/user/bot/lcbot/venv/lib/python3.11/site-packages/aiogram/fsm/middleware.py", line 41, in __call__
    return await handler(event, data)
           ^^^^^^^^^^^^^^^^^^^^^^^^^^
  File "/home/user/bot/lcbot/venv/lib/python3.11/site-packages/aiogram/dispatcher/event/telegram.py", line 120, in trigger
    return await wrapped_inner(event, kwargs)
           ^^^^^^^^^^^^^^^^^^^^^^^^^^^^^^^^^^
  File "/home/user/bot/lcbot/venv/lib/python3.11/site-packages/aiogram/dispatcher/event/handler.py", line 42, in call
    return await wrapped()
           ^^^^^^^^^^^^^^^
  File "/home/user/bot/lcbot/venv/lib/python3.11/site-packages/aiogram/dispatcher/dispatcher.py", line 275, in _listen_update
    return await self.propagate_event(update_type=update_type, event=event, **kwargs)
           ^^^^^^^^^^^^^^^^^^^^^^^^^^^^^^^^^^^^^^^^^^^^^^^^^^^^^^^^^^^^^^^^^^^^^^^^^^
  File "/home/user/bot/lcbot/venv/lib/python3.11/site-packages/aiogram/dispatcher/router.py", line 116, in propagate_event
    return await observer.wrap_outer_middleware(_wrapped, event=event, data=kwargs)
           ^^^^^^^^^^^^^^^^^^^^^^^^^^^^^^^^^^^^^^^^^^^^^^^^^^^^^^^^^^^^^^^^^^^^^^^^
  File "/home/user/bot/lcbot/venv/lib/python3.11/site-packages/aiogram/dispatcher/router.py", line 111, in _wrapped
    return await self._propagate_event(
           ^^^^^^^^^^^^^^^^^^^^^^^^^^^^
  File "/home/user/bot/lcbot/venv/lib/python3.11/site-packages/aiogram/dispatcher/router.py", line 136, in _propagate_event
    response = await observer.trigger(event, **kwargs)
               ^^^^^^^^^^^^^^^^^^^^^^^^^^^^^^^^^^^^^^^
  File "/home/user/bot/lcbot/venv/lib/python3.11/site-packages/aiogram/dispatcher/event/telegram.py", line 120, in trigger
    return await wrapped_inner(event, kwargs)
           ^^^^^^^^^^^^^^^^^^^^^^^^^^^^^^^^^^
  File "/home/user/bot/lcbot/venv/lib/python3.11/site-packages/aiogram/dispatcher/event/handler.py", line 42, in call
    return await wrapped()
           ^^^^^^^^^^^^^^^
  File "/home/user/bot/lcbot/bot.py", line 110, in check_imei
    device = imei_device[1].split(": ")[1] + " " + imei_device[3].split(": ")[1]
             ~~~~~~~~~~~^^^
IndexError: list index out of range
2024-02-09 10:42:30,438 INFO Update id=774151630 is handled. Duration 538 ms by bot id=6523255231
2024-02-09 10:54:37,245 INFO Update id=774151631 is handled. Duration 906 ms by bot id=6523255231
2024-02-09 10:54:48,741 INFO Update id=774151632 is handled. Duration 342 ms by bot id=6523255231
2024-02-09 10:54:52,931 INFO Update id=774151633 is not handled. Duration 1 ms by bot id=6523255231
2024-02-09 10:54:52,931 ERROR Cause exception while process update id=774151633 by bot id=6523255231
FileNotFoundError: [Errno 2] No such file or directory: '/home/user/smscenter/sms/sent/9086760001-A3dz0Z.txt'
Traceback (most recent call last):
  File "/home/user/bot/lcbot/venv/lib/python3.11/site-packages/aiogram/dispatcher/dispatcher.py", line 308, in _process_update
    response = await self.feed_update(bot, update, **kwargs)
               ^^^^^^^^^^^^^^^^^^^^^^^^^^^^^^^^^^^^^^^^^^^^^
  File "/home/user/bot/lcbot/venv/lib/python3.11/site-packages/aiogram/dispatcher/dispatcher.py", line 157, in feed_update
    response = await self.update.wrap_outer_middleware(
               ^^^^^^^^^^^^^^^^^^^^^^^^^^^^^^^^^^^^^^^^
  File "/home/user/bot/lcbot/venv/lib/python3.11/site-packages/aiogram/dispatcher/middlewares/error.py", line 25, in __call__
    return await handler(event, data)
           ^^^^^^^^^^^^^^^^^^^^^^^^^^
  File "/home/user/bot/lcbot/venv/lib/python3.11/site-packages/aiogram/dispatcher/middlewares/user_context.py", line 27, in __call__
    return await handler(event, data)
           ^^^^^^^^^^^^^^^^^^^^^^^^^^
  File "/home/user/bot/lcbot/venv/lib/python3.11/site-packages/aiogram/fsm/middleware.py", line 41, in __call__
    return await handler(event, data)
           ^^^^^^^^^^^^^^^^^^^^^^^^^^
  File "/home/user/bot/lcbot/venv/lib/python3.11/site-packages/aiogram/dispatcher/event/telegram.py", line 120, in trigger
    return await wrapped_inner(event, kwargs)
           ^^^^^^^^^^^^^^^^^^^^^^^^^^^^^^^^^^
  File "/home/user/bot/lcbot/venv/lib/python3.11/site-packages/aiogram/dispatcher/event/handler.py", line 42, in call
    return await wrapped()
           ^^^^^^^^^^^^^^^
  File "/home/user/bot/lcbot/venv/lib/python3.11/site-packages/aiogram/dispatcher/dispatcher.py", line 275, in _listen_update
    return await self.propagate_event(update_type=update_type, event=event, **kwargs)
           ^^^^^^^^^^^^^^^^^^^^^^^^^^^^^^^^^^^^^^^^^^^^^^^^^^^^^^^^^^^^^^^^^^^^^^^^^^
  File "/home/user/bot/lcbot/venv/lib/python3.11/site-packages/aiogram/dispatcher/router.py", line 116, in propagate_event
    return await observer.wrap_outer_middleware(_wrapped, event=event, data=kwargs)
           ^^^^^^^^^^^^^^^^^^^^^^^^^^^^^^^^^^^^^^^^^^^^^^^^^^^^^^^^^^^^^^^^^^^^^^^^
  File "/home/user/bot/lcbot/venv/lib/python3.11/site-packages/aiogram/dispatcher/router.py", line 111, in _wrapped
    return await self._propagate_event(
           ^^^^^^^^^^^^^^^^^^^^^^^^^^^^
  File "/home/user/bot/lcbot/venv/lib/python3.11/site-packages/aiogram/dispatcher/router.py", line 136, in _propagate_event
    response = await observer.trigger(event, **kwargs)
               ^^^^^^^^^^^^^^^^^^^^^^^^^^^^^^^^^^^^^^^
  File "/home/user/bot/lcbot/venv/lib/python3.11/site-packages/aiogram/dispatcher/event/telegram.py", line 120, in trigger
    return await wrapped_inner(event, kwargs)
           ^^^^^^^^^^^^^^^^^^^^^^^^^^^^^^^^^^
  File "/home/user/bot/lcbot/venv/lib/python3.11/site-packages/aiogram/dispatcher/event/handler.py", line 42, in call
    return await wrapped()
           ^^^^^^^^^^^^^^^
  File "/home/user/bot/lcbot/bot.py", line 269, in update_modem_ping_status
    message_id = await loop.run_in_executor(None, smscenter.get_message_id, filename)
                 ^^^^^^^^^^^^^^^^^^^^^^^^^^^^^^^^^^^^^^^^^^^^^^^^^^^^^^^^^^^^^^^^^^^^
  File "/usr/lib/python3.11/concurrent/futures/thread.py", line 58, in run
    result = self.fn(*self.args, **self.kwargs)
             ^^^^^^^^^^^^^^^^^^^^^^^^^^^^^^^^^^
  File "/home/user/bot/lcbot/smscenter.py", line 20, in get_message_id
    with open(file_check_id_name, "r", encoding="utf-8") as file:
         ^^^^^^^^^^^^^^^^^^^^^^^^^^^^^^^^^^^^^^^^^^^^^^^
FileNotFoundError: [Errno 2] No such file or directory: '/home/user/smscenter/sms/sent/9086760001-A3dz0Z.txt'
2024-02-09 10:55:10,267 INFO Update id=774151634 is handled. Duration 311 ms by bot id=6523255231
2024-02-09 10:56:18,067 INFO Update id=774151636 is handled. Duration 339 ms by bot id=6523255231
2024-02-09 10:56:19,712 INFO Update id=774151635 is handled. Duration 60388 ms by bot id=6523255231
2024-02-09 10:56:30,627 INFO Update id=774151637 is handled. Duration 429 ms by bot id=6523255231
2024-02-09 10:57:06,715 INFO Update id=774151639 is handled. Duration 330 ms by bot id=6523255231
2024-02-09 10:57:24,580 INFO Update id=774151640 is handled. Duration 474 ms by bot id=6523255231
2024-02-09 10:57:37,633 INFO Update id=774151641 is handled. Duration 925 ms by bot id=6523255231
2024-02-09 10:58:00,202 INFO Update id=774151638 is not handled. Duration 60006 ms by bot id=6523255231
2024-02-09 10:58:00,202 ERROR Cause exception while process update id=774151638 by bot id=6523255231
TelegramNetworkError: HTTP Client says - ClientConnectorError: Cannot connect to host api.telegram.org:443 ssl:default [Network is unreachable]
Traceback (most recent call last):
  File "/home/user/bot/lcbot/venv/lib/python3.11/site-packages/aiohttp/connector.py", line 980, in _wrap_create_connection
    return await self._loop.create_connection(*args, **kwargs)  # type: ignore[return-value]  # noqa
           ^^^^^^^^^^^^^^^^^^^^^^^^^^^^^^^^^^^^^^^^^^^^^^^^^^^
  File "/usr/lib/python3.11/asyncio/base_events.py", line 1085, in create_connection
    raise exceptions[0]
  File "/usr/lib/python3.11/asyncio/base_events.py", line 1069, in create_connection
    sock = await self._connect_sock(
           ^^^^^^^^^^^^^^^^^^^^^^^^^
  File "/usr/lib/python3.11/asyncio/base_events.py", line 973, in _connect_sock
    await self.sock_connect(sock, address)
  File "/usr/lib/python3.11/asyncio/selector_events.py", line 634, in sock_connect
    return await fut
           ^^^^^^^^^
  File "/usr/lib/python3.11/asyncio/selector_events.py", line 642, in _sock_connect
    sock.connect(address)
OSError: [Errno 101] Network is unreachable

The above exception was the direct cause of the following exception:

Traceback (most recent call last):
  File "/home/user/bot/lcbot/venv/lib/python3.11/site-packages/aiogram/client/session/aiohttp.py", line 167, in make_request
    async with session.post(
  File "/home/user/bot/lcbot/venv/lib/python3.11/site-packages/aiohttp/client.py", line 1141, in __aenter__
    self._resp = await self._coro
                 ^^^^^^^^^^^^^^^^
  File "/home/user/bot/lcbot/venv/lib/python3.11/site-packages/aiohttp/client.py", line 536, in _request
    conn = await self._connector.connect(
           ^^^^^^^^^^^^^^^^^^^^^^^^^^^^^^
  File "/home/user/bot/lcbot/venv/lib/python3.11/site-packages/aiohttp/connector.py", line 540, in connect
    proto = await self._create_connection(req, traces, timeout)
            ^^^^^^^^^^^^^^^^^^^^^^^^^^^^^^^^^^^^^^^^^^^^^^^^^^^
  File "/home/user/bot/lcbot/venv/lib/python3.11/site-packages/aiohttp/connector.py", line 901, in _create_connection
    _, proto = await self._create_direct_connection(req, traces, timeout)
               ^^^^^^^^^^^^^^^^^^^^^^^^^^^^^^^^^^^^^^^^^^^^^^^^^^^^^^^^^^
  File "/home/user/bot/lcbot/venv/lib/python3.11/site-packages/aiohttp/connector.py", line 1209, in _create_direct_connection
    raise last_exc
  File "/home/user/bot/lcbot/venv/lib/python3.11/site-packages/aiohttp/connector.py", line 1178, in _create_direct_connection
    transp, proto = await self._wrap_create_connection(
                    ^^^^^^^^^^^^^^^^^^^^^^^^^^^^^^^^^^^
  File "/home/user/bot/lcbot/venv/lib/python3.11/site-packages/aiohttp/connector.py", line 988, in _wrap_create_connection
    raise client_error(req.connection_key, exc) from exc
aiohttp.client_exceptions.ClientConnectorError: Cannot connect to host api.telegram.org:443 ssl:default [Network is unreachable]

During handling of the above exception, another exception occurred:

Traceback (most recent call last):
  File "/home/user/bot/lcbot/venv/lib/python3.11/site-packages/aiogram/dispatcher/dispatcher.py", line 308, in _process_update
    response = await self.feed_update(bot, update, **kwargs)
               ^^^^^^^^^^^^^^^^^^^^^^^^^^^^^^^^^^^^^^^^^^^^^
  File "/home/user/bot/lcbot/venv/lib/python3.11/site-packages/aiogram/dispatcher/dispatcher.py", line 157, in feed_update
    response = await self.update.wrap_outer_middleware(
               ^^^^^^^^^^^^^^^^^^^^^^^^^^^^^^^^^^^^^^^^
  File "/home/user/bot/lcbot/venv/lib/python3.11/site-packages/aiogram/dispatcher/middlewares/error.py", line 25, in __call__
    return await handler(event, data)
           ^^^^^^^^^^^^^^^^^^^^^^^^^^
  File "/home/user/bot/lcbot/venv/lib/python3.11/site-packages/aiogram/dispatcher/middlewares/user_context.py", line 27, in __call__
    return await handler(event, data)
           ^^^^^^^^^^^^^^^^^^^^^^^^^^
  File "/home/user/bot/lcbot/venv/lib/python3.11/site-packages/aiogram/fsm/middleware.py", line 41, in __call__
    return await handler(event, data)
           ^^^^^^^^^^^^^^^^^^^^^^^^^^
  File "/home/user/bot/lcbot/venv/lib/python3.11/site-packages/aiogram/dispatcher/event/telegram.py", line 120, in trigger
    return await wrapped_inner(event, kwargs)
           ^^^^^^^^^^^^^^^^^^^^^^^^^^^^^^^^^^
  File "/home/user/bot/lcbot/venv/lib/python3.11/site-packages/aiogram/dispatcher/event/handler.py", line 42, in call
    return await wrapped()
           ^^^^^^^^^^^^^^^
  File "/home/user/bot/lcbot/venv/lib/python3.11/site-packages/aiogram/dispatcher/dispatcher.py", line 275, in _listen_update
    return await self.propagate_event(update_type=update_type, event=event, **kwargs)
           ^^^^^^^^^^^^^^^^^^^^^^^^^^^^^^^^^^^^^^^^^^^^^^^^^^^^^^^^^^^^^^^^^^^^^^^^^^
  File "/home/user/bot/lcbot/venv/lib/python3.11/site-packages/aiogram/dispatcher/router.py", line 116, in propagate_event
    return await observer.wrap_outer_middleware(_wrapped, event=event, data=kwargs)
           ^^^^^^^^^^^^^^^^^^^^^^^^^^^^^^^^^^^^^^^^^^^^^^^^^^^^^^^^^^^^^^^^^^^^^^^^
  File "/home/user/bot/lcbot/venv/lib/python3.11/site-packages/aiogram/dispatcher/router.py", line 111, in _wrapped
    return await self._propagate_event(
           ^^^^^^^^^^^^^^^^^^^^^^^^^^^^
  File "/home/user/bot/lcbot/venv/lib/python3.11/site-packages/aiogram/dispatcher/router.py", line 136, in _propagate_event
    response = await observer.trigger(event, **kwargs)
               ^^^^^^^^^^^^^^^^^^^^^^^^^^^^^^^^^^^^^^^
  File "/home/user/bot/lcbot/venv/lib/python3.11/site-packages/aiogram/dispatcher/event/telegram.py", line 120, in trigger
    return await wrapped_inner(event, kwargs)
           ^^^^^^^^^^^^^^^^^^^^^^^^^^^^^^^^^^
  File "/home/user/bot/lcbot/venv/lib/python3.11/site-packages/aiogram/dispatcher/event/handler.py", line 42, in call
    return await wrapped()
           ^^^^^^^^^^^^^^^
  File "/home/user/bot/lcbot/bot.py", line 349, in cmd_help
    await message.answer(
  File "/home/user/bot/lcbot/venv/lib/python3.11/site-packages/aiogram/methods/base.py", line 84, in emit
    return await bot(self)
           ^^^^^^^^^^^^^^^
  File "/home/user/bot/lcbot/venv/lib/python3.11/site-packages/aiogram/client/bot.py", line 432, in __call__
    return await self.session(self, method, timeout=request_timeout)
           ^^^^^^^^^^^^^^^^^^^^^^^^^^^^^^^^^^^^^^^^^^^^^^^^^^^^^^^^^
  File "/home/user/bot/lcbot/venv/lib/python3.11/site-packages/aiogram/client/session/base.py", line 257, in __call__
    return cast(TelegramType, await middleware(bot, method))
                              ^^^^^^^^^^^^^^^^^^^^^^^^^^^^^
  File "/home/user/bot/lcbot/venv/lib/python3.11/site-packages/aiogram/client/session/aiohttp.py", line 174, in make_request
    raise TelegramNetworkError(method=method, message=f"{type(e).__name__}: {e}")
aiogram.exceptions.TelegramNetworkError: HTTP Client says - ClientConnectorError: Cannot connect to host api.telegram.org:443 ssl:default [Network is unreachable]
2024-02-09 10:58:57,841 INFO Update id=774151642 is handled. Duration 4015 ms by bot id=6523255231
2024-02-09 12:07:35,373 INFO Update id=774151643 is handled. Duration 553 ms by bot id=6523255231
2024-02-09 12:38:51,250 INFO Update id=774151644 is handled. Duration 1989 ms by bot id=6523255231
2024-02-09 12:39:23,283 INFO Update id=774151645 is handled. Duration 3802 ms by bot id=6523255231
2024-02-09 14:28:11,039 INFO Update id=774151646 is handled. Duration 436 ms by bot id=6523255231
2024-02-09 14:28:18,693 INFO Update id=774151647 is handled. Duration 213 ms by bot id=6523255231
2024-02-09 14:28:30,337 INFO Update id=774151648 is handled. Duration 442 ms by bot id=6523255231
2024-02-09 14:29:58,080 INFO Update id=774151649 is handled. Duration 60568 ms by bot id=6523255231
2024-02-09 15:59:37,610 INFO Update id=774151650 is handled. Duration 60761 ms by bot id=6523255231
2024-02-09 16:01:28,198 INFO Update id=774151651 is handled. Duration 60760 ms by bot id=6523255231
2024-02-09 16:02:54,030 INFO Update id=774151652 is handled. Duration 60609 ms by bot id=6523255231
2024-02-09 16:06:31,164 INFO Update id=774151653 is handled. Duration 60663 ms by bot id=6523255231
2024-02-09 16:13:25,803 INFO Update id=774151654 is handled. Duration 60651 ms by bot id=6523255231
2024-02-09 16:23:19,476 INFO Update id=774151655 is handled. Duration 60715 ms by bot id=6523255231
2024-02-09 16:26:09,530 INFO Update id=774151656 is handled. Duration 60625 ms by bot id=6523255231
2024-02-09 16:31:23,369 INFO Update id=774151657 is handled. Duration 60870 ms by bot id=6523255231
2024-02-09 16:42:19,405 INFO Update id=774151658 is handled. Duration 836 ms by bot id=6523255231
2024-02-09 16:42:25,728 INFO Update id=774151659 is handled. Duration 316 ms by bot id=6523255231
2024-02-09 16:46:36,098 INFO Update id=774151660 is handled. Duration 303 ms by bot id=6523255231
2024-02-09 16:52:52,779 INFO Update id=774151661 is handled. Duration 60612 ms by bot id=6523255231
2024-02-09 16:56:16,714 INFO Update id=774151662 is handled. Duration 60637 ms by bot id=6523255231
2024-02-09 17:04:24,244 INFO Update id=774151663 is handled. Duration 60595 ms by bot id=6523255231
2024-02-09 17:09:08,671 INFO Update id=774151664 is handled. Duration 60511 ms by bot id=6523255231
2024-02-09 22:29:04,637 ERROR Failed to fetch updates - TelegramNetworkError: HTTP Client says - ClientConnectorError: Cannot connect to host api.telegram.org:443 ssl:default [Network is unreachable]
2024-02-09 22:29:04,637 WARNING Sleep for 1.000000 seconds and try again... (tryings = 0, bot id = 6523255231)
2024-02-09 22:29:15,896 INFO Connection established (tryings = 1, bot id = 6523255231)
2024-02-10 04:02:03,014 ERROR Failed to fetch updates - TelegramNetworkError: HTTP Client says - ServerDisconnectedError: Server disconnected
2024-02-10 04:02:03,014 WARNING Sleep for 1.000000 seconds and try again... (tryings = 0, bot id = 6523255231)
2024-02-10 04:02:14,334 INFO Connection established (tryings = 1, bot id = 6523255231)
2024-02-10 12:10:57,760 INFO Update id=774151665 is handled. Duration 4935 ms by bot id=6523255231
2024-02-10 12:11:46,337 INFO Update id=774151666 is handled. Duration 3765 ms by bot id=6523255231
2024-02-10 12:15:15,963 INFO Update id=774151667 is handled. Duration 3877 ms by bot id=6523255231
2024-02-10 12:48:05,272 INFO Update id=774151668 is handled. Duration 2272 ms by bot id=6523255231
2024-02-10 12:49:20,037 INFO Update id=774151669 is handled. Duration 2093 ms by bot id=6523255231
2024-02-10 12:49:50,623 INFO Update id=774151670 is handled. Duration 297 ms by bot id=6523255231
2024-02-10 12:50:07,825 INFO Update id=774151671 is handled. Duration 1986 ms by bot id=6523255231
2024-02-10 12:50:35,432 INFO Update id=774151672 is handled. Duration 1754 ms by bot id=6523255231
2024-02-10 15:56:12,847 INFO Update id=774151673 is not handled. Duration 5032 ms by bot id=6523255231
2024-02-10 15:56:12,847 ERROR Cause exception while process update id=774151673 by bot id=6523255231
IndexError: list index out of range
Traceback (most recent call last):
  File "/home/user/bot/lcbot/venv/lib/python3.11/site-packages/aiogram/dispatcher/dispatcher.py", line 308, in _process_update
    response = await self.feed_update(bot, update, **kwargs)
               ^^^^^^^^^^^^^^^^^^^^^^^^^^^^^^^^^^^^^^^^^^^^^
  File "/home/user/bot/lcbot/venv/lib/python3.11/site-packages/aiogram/dispatcher/dispatcher.py", line 157, in feed_update
    response = await self.update.wrap_outer_middleware(
               ^^^^^^^^^^^^^^^^^^^^^^^^^^^^^^^^^^^^^^^^
  File "/home/user/bot/lcbot/venv/lib/python3.11/site-packages/aiogram/dispatcher/middlewares/error.py", line 25, in __call__
    return await handler(event, data)
           ^^^^^^^^^^^^^^^^^^^^^^^^^^
  File "/home/user/bot/lcbot/venv/lib/python3.11/site-packages/aiogram/dispatcher/middlewares/user_context.py", line 27, in __call__
    return await handler(event, data)
           ^^^^^^^^^^^^^^^^^^^^^^^^^^
  File "/home/user/bot/lcbot/venv/lib/python3.11/site-packages/aiogram/fsm/middleware.py", line 41, in __call__
    return await handler(event, data)
           ^^^^^^^^^^^^^^^^^^^^^^^^^^
  File "/home/user/bot/lcbot/venv/lib/python3.11/site-packages/aiogram/dispatcher/event/telegram.py", line 120, in trigger
    return await wrapped_inner(event, kwargs)
           ^^^^^^^^^^^^^^^^^^^^^^^^^^^^^^^^^^
  File "/home/user/bot/lcbot/venv/lib/python3.11/site-packages/aiogram/dispatcher/event/handler.py", line 42, in call
    return await wrapped()
           ^^^^^^^^^^^^^^^
  File "/home/user/bot/lcbot/venv/lib/python3.11/site-packages/aiogram/dispatcher/dispatcher.py", line 275, in _listen_update
    return await self.propagate_event(update_type=update_type, event=event, **kwargs)
           ^^^^^^^^^^^^^^^^^^^^^^^^^^^^^^^^^^^^^^^^^^^^^^^^^^^^^^^^^^^^^^^^^^^^^^^^^^
  File "/home/user/bot/lcbot/venv/lib/python3.11/site-packages/aiogram/dispatcher/router.py", line 116, in propagate_event
    return await observer.wrap_outer_middleware(_wrapped, event=event, data=kwargs)
           ^^^^^^^^^^^^^^^^^^^^^^^^^^^^^^^^^^^^^^^^^^^^^^^^^^^^^^^^^^^^^^^^^^^^^^^^
  File "/home/user/bot/lcbot/venv/lib/python3.11/site-packages/aiogram/dispatcher/router.py", line 111, in _wrapped
    return await self._propagate_event(
           ^^^^^^^^^^^^^^^^^^^^^^^^^^^^
  File "/home/user/bot/lcbot/venv/lib/python3.11/site-packages/aiogram/dispatcher/router.py", line 136, in _propagate_event
    response = await observer.trigger(event, **kwargs)
               ^^^^^^^^^^^^^^^^^^^^^^^^^^^^^^^^^^^^^^^
  File "/home/user/bot/lcbot/venv/lib/python3.11/site-packages/aiogram/dispatcher/event/telegram.py", line 120, in trigger
    return await wrapped_inner(event, kwargs)
           ^^^^^^^^^^^^^^^^^^^^^^^^^^^^^^^^^^
  File "/home/user/bot/lcbot/venv/lib/python3.11/site-packages/aiogram/dispatcher/event/handler.py", line 42, in call
    return await wrapped()
           ^^^^^^^^^^^^^^^
  File "/home/user/bot/lcbot/bot.py", line 110, in check_imei
    device = imei_device[1].split(": ")[1] + " " + imei_device[3].split(": ")[1]
             ~~~~~~~~~~~^^^
IndexError: list index out of range
2024-02-11 04:02:03,053 ERROR Failed to fetch updates - TelegramNetworkError: HTTP Client says - ServerDisconnectedError: Server disconnected
2024-02-11 04:02:03,053 WARNING Sleep for 1.000000 seconds and try again... (tryings = 0, bot id = 6523255231)
2024-02-11 04:02:14,355 INFO Connection established (tryings = 1, bot id = 6523255231)
2024-02-11 21:40:25,504 INFO Update id=774151674 is handled. Duration 345 ms by bot id=6523255231
2024-02-12 04:02:02,681 ERROR Failed to fetch updates - TelegramNetworkError: HTTP Client says - ServerDisconnectedError: Server disconnected
2024-02-12 04:02:02,681 WARNING Sleep for 1.000000 seconds and try again... (tryings = 0, bot id = 6523255231)
2024-02-12 04:02:13,979 INFO Connection established (tryings = 1, bot id = 6523255231)
2024-02-12 08:58:28,753 INFO Update id=774151675 is handled. Duration 830 ms by bot id=6523255231
2024-02-12 08:58:31,878 INFO Update id=774151676 is handled. Duration 289 ms by bot id=6523255231
2024-02-12 08:58:33,507 INFO Update id=774151677 is not handled. Duration 0 ms by bot id=6523255231
2024-02-12 08:58:33,508 ERROR Cause exception while process update id=774151677 by bot id=6523255231
FileNotFoundError: [Errno 2] No such file or directory: '/home/user/smscenter/sms/sent/9898267167-lFUBXn.txt'
Traceback (most recent call last):
  File "/home/user/bot/lcbot/venv/lib/python3.11/site-packages/aiogram/dispatcher/dispatcher.py", line 308, in _process_update
    response = await self.feed_update(bot, update, **kwargs)
               ^^^^^^^^^^^^^^^^^^^^^^^^^^^^^^^^^^^^^^^^^^^^^
  File "/home/user/bot/lcbot/venv/lib/python3.11/site-packages/aiogram/dispatcher/dispatcher.py", line 157, in feed_update
    response = await self.update.wrap_outer_middleware(
               ^^^^^^^^^^^^^^^^^^^^^^^^^^^^^^^^^^^^^^^^
  File "/home/user/bot/lcbot/venv/lib/python3.11/site-packages/aiogram/dispatcher/middlewares/error.py", line 25, in __call__
    return await handler(event, data)
           ^^^^^^^^^^^^^^^^^^^^^^^^^^
  File "/home/user/bot/lcbot/venv/lib/python3.11/site-packages/aiogram/dispatcher/middlewares/user_context.py", line 27, in __call__
    return await handler(event, data)
           ^^^^^^^^^^^^^^^^^^^^^^^^^^
  File "/home/user/bot/lcbot/venv/lib/python3.11/site-packages/aiogram/fsm/middleware.py", line 41, in __call__
    return await handler(event, data)
           ^^^^^^^^^^^^^^^^^^^^^^^^^^
  File "/home/user/bot/lcbot/venv/lib/python3.11/site-packages/aiogram/dispatcher/event/telegram.py", line 120, in trigger
    return await wrapped_inner(event, kwargs)
           ^^^^^^^^^^^^^^^^^^^^^^^^^^^^^^^^^^
  File "/home/user/bot/lcbot/venv/lib/python3.11/site-packages/aiogram/dispatcher/event/handler.py", line 42, in call
    return await wrapped()
           ^^^^^^^^^^^^^^^
  File "/home/user/bot/lcbot/venv/lib/python3.11/site-packages/aiogram/dispatcher/dispatcher.py", line 275, in _listen_update
    return await self.propagate_event(update_type=update_type, event=event, **kwargs)
           ^^^^^^^^^^^^^^^^^^^^^^^^^^^^^^^^^^^^^^^^^^^^^^^^^^^^^^^^^^^^^^^^^^^^^^^^^^
  File "/home/user/bot/lcbot/venv/lib/python3.11/site-packages/aiogram/dispatcher/router.py", line 116, in propagate_event
    return await observer.wrap_outer_middleware(_wrapped, event=event, data=kwargs)
           ^^^^^^^^^^^^^^^^^^^^^^^^^^^^^^^^^^^^^^^^^^^^^^^^^^^^^^^^^^^^^^^^^^^^^^^^
  File "/home/user/bot/lcbot/venv/lib/python3.11/site-packages/aiogram/dispatcher/router.py", line 111, in _wrapped
    return await self._propagate_event(
           ^^^^^^^^^^^^^^^^^^^^^^^^^^^^
  File "/home/user/bot/lcbot/venv/lib/python3.11/site-packages/aiogram/dispatcher/router.py", line 136, in _propagate_event
    response = await observer.trigger(event, **kwargs)
               ^^^^^^^^^^^^^^^^^^^^^^^^^^^^^^^^^^^^^^^
  File "/home/user/bot/lcbot/venv/lib/python3.11/site-packages/aiogram/dispatcher/event/telegram.py", line 120, in trigger
    return await wrapped_inner(event, kwargs)
           ^^^^^^^^^^^^^^^^^^^^^^^^^^^^^^^^^^
  File "/home/user/bot/lcbot/venv/lib/python3.11/site-packages/aiogram/dispatcher/event/handler.py", line 42, in call
    return await wrapped()
           ^^^^^^^^^^^^^^^
  File "/home/user/bot/lcbot/bot.py", line 269, in update_modem_ping_status
    message_id = await loop.run_in_executor(None, smscenter.get_message_id, filename)
                 ^^^^^^^^^^^^^^^^^^^^^^^^^^^^^^^^^^^^^^^^^^^^^^^^^^^^^^^^^^^^^^^^^^^^
  File "/usr/lib/python3.11/concurrent/futures/thread.py", line 58, in run
    result = self.fn(*self.args, **self.kwargs)
             ^^^^^^^^^^^^^^^^^^^^^^^^^^^^^^^^^^
  File "/home/user/bot/lcbot/smscenter.py", line 20, in get_message_id
    with open(file_check_id_name, "r", encoding="utf-8") as file:
         ^^^^^^^^^^^^^^^^^^^^^^^^^^^^^^^^^^^^^^^^^^^^^^^
FileNotFoundError: [Errno 2] No such file or directory: '/home/user/smscenter/sms/sent/9898267167-lFUBXn.txt'
2024-02-12 08:58:45,451 INFO Update id=774151678 is handled. Duration 101 ms by bot id=6523255231
2024-02-12 08:58:46,952 INFO Update id=774151679 is handled. Duration 100 ms by bot id=6523255231
2024-02-12 08:58:47,962 INFO Update id=774151680 is handled. Duration 104 ms by bot id=6523255231
2024-02-12 08:58:48,952 INFO Update id=774151681 is handled. Duration 163 ms by bot id=6523255231
2024-02-12 08:58:50,023 INFO Update id=774151682 is handled. Duration 150 ms by bot id=6523255231
2024-02-12 08:58:51,275 INFO Update id=774151683 is handled. Duration 122 ms by bot id=6523255231
2024-02-12 09:39:39,401 INFO Update id=774151684 is handled. Duration 330 ms by bot id=6523255231
2024-02-12 09:39:39,425 INFO Update id=774151685 is handled. Duration 353 ms by bot id=6523255231
2024-02-12 09:39:39,444 INFO Update id=774151687 is handled. Duration 305 ms by bot id=6523255231
2024-02-12 09:39:39,473 INFO Update id=774151686 is handled. Duration 401 ms by bot id=6523255231
2024-02-12 09:39:39,492 INFO Update id=774151688 is handled. Duration 352 ms by bot id=6523255231
2024-02-12 10:18:25,841 INFO Update id=774151689 is handled. Duration 734 ms by bot id=6523255231
2024-02-12 10:18:27,856 INFO Update id=774151690 is handled. Duration 943 ms by bot id=6523255231
2024-02-12 10:18:29,307 INFO Update id=774151691 is not handled. Duration 1 ms by bot id=6523255231
2024-02-12 10:18:29,307 ERROR Cause exception while process update id=774151691 by bot id=6523255231
FileNotFoundError: [Errno 2] No such file or directory: '/home/user/smscenter/sms/sent/9898267167-9XpJBl.txt'
Traceback (most recent call last):
  File "/home/user/bot/lcbot/venv/lib/python3.11/site-packages/aiogram/dispatcher/dispatcher.py", line 308, in _process_update
    response = await self.feed_update(bot, update, **kwargs)
               ^^^^^^^^^^^^^^^^^^^^^^^^^^^^^^^^^^^^^^^^^^^^^
  File "/home/user/bot/lcbot/venv/lib/python3.11/site-packages/aiogram/dispatcher/dispatcher.py", line 157, in feed_update
    response = await self.update.wrap_outer_middleware(
               ^^^^^^^^^^^^^^^^^^^^^^^^^^^^^^^^^^^^^^^^
  File "/home/user/bot/lcbot/venv/lib/python3.11/site-packages/aiogram/dispatcher/middlewares/error.py", line 25, in __call__
    return await handler(event, data)
           ^^^^^^^^^^^^^^^^^^^^^^^^^^
  File "/home/user/bot/lcbot/venv/lib/python3.11/site-packages/aiogram/dispatcher/middlewares/user_context.py", line 27, in __call__
    return await handler(event, data)
           ^^^^^^^^^^^^^^^^^^^^^^^^^^
  File "/home/user/bot/lcbot/venv/lib/python3.11/site-packages/aiogram/fsm/middleware.py", line 41, in __call__
    return await handler(event, data)
           ^^^^^^^^^^^^^^^^^^^^^^^^^^
  File "/home/user/bot/lcbot/venv/lib/python3.11/site-packages/aiogram/dispatcher/event/telegram.py", line 120, in trigger
    return await wrapped_inner(event, kwargs)
           ^^^^^^^^^^^^^^^^^^^^^^^^^^^^^^^^^^
  File "/home/user/bot/lcbot/venv/lib/python3.11/site-packages/aiogram/dispatcher/event/handler.py", line 42, in call
    return await wrapped()
           ^^^^^^^^^^^^^^^
  File "/home/user/bot/lcbot/venv/lib/python3.11/site-packages/aiogram/dispatcher/dispatcher.py", line 275, in _listen_update
    return await self.propagate_event(update_type=update_type, event=event, **kwargs)
           ^^^^^^^^^^^^^^^^^^^^^^^^^^^^^^^^^^^^^^^^^^^^^^^^^^^^^^^^^^^^^^^^^^^^^^^^^^
  File "/home/user/bot/lcbot/venv/lib/python3.11/site-packages/aiogram/dispatcher/router.py", line 116, in propagate_event
    return await observer.wrap_outer_middleware(_wrapped, event=event, data=kwargs)
           ^^^^^^^^^^^^^^^^^^^^^^^^^^^^^^^^^^^^^^^^^^^^^^^^^^^^^^^^^^^^^^^^^^^^^^^^
  File "/home/user/bot/lcbot/venv/lib/python3.11/site-packages/aiogram/dispatcher/router.py", line 111, in _wrapped
    return await self._propagate_event(
           ^^^^^^^^^^^^^^^^^^^^^^^^^^^^
  File "/home/user/bot/lcbot/venv/lib/python3.11/site-packages/aiogram/dispatcher/router.py", line 136, in _propagate_event
    response = await observer.trigger(event, **kwargs)
               ^^^^^^^^^^^^^^^^^^^^^^^^^^^^^^^^^^^^^^^
  File "/home/user/bot/lcbot/venv/lib/python3.11/site-packages/aiogram/dispatcher/event/telegram.py", line 120, in trigger
    return await wrapped_inner(event, kwargs)
           ^^^^^^^^^^^^^^^^^^^^^^^^^^^^^^^^^^
  File "/home/user/bot/lcbot/venv/lib/python3.11/site-packages/aiogram/dispatcher/event/handler.py", line 42, in call
    return await wrapped()
           ^^^^^^^^^^^^^^^
  File "/home/user/bot/lcbot/bot.py", line 269, in update_modem_ping_status
    message_id = await loop.run_in_executor(None, smscenter.get_message_id, filename)
                 ^^^^^^^^^^^^^^^^^^^^^^^^^^^^^^^^^^^^^^^^^^^^^^^^^^^^^^^^^^^^^^^^^^^^
  File "/usr/lib/python3.11/concurrent/futures/thread.py", line 58, in run
    result = self.fn(*self.args, **self.kwargs)
             ^^^^^^^^^^^^^^^^^^^^^^^^^^^^^^^^^^
  File "/home/user/bot/lcbot/smscenter.py", line 20, in get_message_id
    with open(file_check_id_name, "r", encoding="utf-8") as file:
         ^^^^^^^^^^^^^^^^^^^^^^^^^^^^^^^^^^^^^^^^^^^^^^^
FileNotFoundError: [Errno 2] No such file or directory: '/home/user/smscenter/sms/sent/9898267167-9XpJBl.txt'
2024-02-12 10:18:32,871 INFO Update id=774151692 is not handled. Duration 1 ms by bot id=6523255231
2024-02-12 10:18:32,871 ERROR Cause exception while process update id=774151692 by bot id=6523255231
FileNotFoundError: [Errno 2] No such file or directory: '/home/user/smscenter/sms/sent/9898267167-9XpJBl.txt'
Traceback (most recent call last):
  File "/home/user/bot/lcbot/venv/lib/python3.11/site-packages/aiogram/dispatcher/dispatcher.py", line 308, in _process_update
    response = await self.feed_update(bot, update, **kwargs)
               ^^^^^^^^^^^^^^^^^^^^^^^^^^^^^^^^^^^^^^^^^^^^^
  File "/home/user/bot/lcbot/venv/lib/python3.11/site-packages/aiogram/dispatcher/dispatcher.py", line 157, in feed_update
    response = await self.update.wrap_outer_middleware(
               ^^^^^^^^^^^^^^^^^^^^^^^^^^^^^^^^^^^^^^^^
  File "/home/user/bot/lcbot/venv/lib/python3.11/site-packages/aiogram/dispatcher/middlewares/error.py", line 25, in __call__
    return await handler(event, data)
           ^^^^^^^^^^^^^^^^^^^^^^^^^^
  File "/home/user/bot/lcbot/venv/lib/python3.11/site-packages/aiogram/dispatcher/middlewares/user_context.py", line 27, in __call__
    return await handler(event, data)
           ^^^^^^^^^^^^^^^^^^^^^^^^^^
  File "/home/user/bot/lcbot/venv/lib/python3.11/site-packages/aiogram/fsm/middleware.py", line 41, in __call__
    return await handler(event, data)
           ^^^^^^^^^^^^^^^^^^^^^^^^^^
  File "/home/user/bot/lcbot/venv/lib/python3.11/site-packages/aiogram/dispatcher/event/telegram.py", line 120, in trigger
    return await wrapped_inner(event, kwargs)
           ^^^^^^^^^^^^^^^^^^^^^^^^^^^^^^^^^^
  File "/home/user/bot/lcbot/venv/lib/python3.11/site-packages/aiogram/dispatcher/event/handler.py", line 42, in call
    return await wrapped()
           ^^^^^^^^^^^^^^^
  File "/home/user/bot/lcbot/venv/lib/python3.11/site-packages/aiogram/dispatcher/dispatcher.py", line 275, in _listen_update
    return await self.propagate_event(update_type=update_type, event=event, **kwargs)
           ^^^^^^^^^^^^^^^^^^^^^^^^^^^^^^^^^^^^^^^^^^^^^^^^^^^^^^^^^^^^^^^^^^^^^^^^^^
  File "/home/user/bot/lcbot/venv/lib/python3.11/site-packages/aiogram/dispatcher/router.py", line 116, in propagate_event
    return await observer.wrap_outer_middleware(_wrapped, event=event, data=kwargs)
           ^^^^^^^^^^^^^^^^^^^^^^^^^^^^^^^^^^^^^^^^^^^^^^^^^^^^^^^^^^^^^^^^^^^^^^^^
  File "/home/user/bot/lcbot/venv/lib/python3.11/site-packages/aiogram/dispatcher/router.py", line 111, in _wrapped
    return await self._propagate_event(
           ^^^^^^^^^^^^^^^^^^^^^^^^^^^^
  File "/home/user/bot/lcbot/venv/lib/python3.11/site-packages/aiogram/dispatcher/router.py", line 136, in _propagate_event
    response = await observer.trigger(event, **kwargs)
               ^^^^^^^^^^^^^^^^^^^^^^^^^^^^^^^^^^^^^^^
  File "/home/user/bot/lcbot/venv/lib/python3.11/site-packages/aiogram/dispatcher/event/telegram.py", line 120, in trigger
    return await wrapped_inner(event, kwargs)
           ^^^^^^^^^^^^^^^^^^^^^^^^^^^^^^^^^^
  File "/home/user/bot/lcbot/venv/lib/python3.11/site-packages/aiogram/dispatcher/event/handler.py", line 42, in call
    return await wrapped()
           ^^^^^^^^^^^^^^^
  File "/home/user/bot/lcbot/bot.py", line 269, in update_modem_ping_status
    message_id = await loop.run_in_executor(None, smscenter.get_message_id, filename)
                 ^^^^^^^^^^^^^^^^^^^^^^^^^^^^^^^^^^^^^^^^^^^^^^^^^^^^^^^^^^^^^^^^^^^^
  File "/usr/lib/python3.11/concurrent/futures/thread.py", line 58, in run
    result = self.fn(*self.args, **self.kwargs)
             ^^^^^^^^^^^^^^^^^^^^^^^^^^^^^^^^^^
  File "/home/user/bot/lcbot/smscenter.py", line 20, in get_message_id
    with open(file_check_id_name, "r", encoding="utf-8") as file:
         ^^^^^^^^^^^^^^^^^^^^^^^^^^^^^^^^^^^^^^^^^^^^^^^
FileNotFoundError: [Errno 2] No such file or directory: '/home/user/smscenter/sms/sent/9898267167-9XpJBl.txt'
2024-02-12 10:18:40,542 INFO Update id=774151693 is handled. Duration 163 ms by bot id=6523255231
2024-02-12 10:18:42,364 INFO Update id=774151694 is handled. Duration 160 ms by bot id=6523255231
2024-02-12 10:18:43,754 INFO Update id=774151695 is handled. Duration 157 ms by bot id=6523255231
2024-02-12 10:18:45,021 INFO Update id=774151696 is handled. Duration 206 ms by bot id=6523255231
2024-02-12 10:19:12,711 INFO Update id=774151697 is handled. Duration 277 ms by bot id=6523255231
2024-02-12 10:31:04,380 INFO Update id=774151698 is handled. Duration 874 ms by bot id=6523255231
2024-02-12 10:31:13,216 INFO Update id=774151699 is handled. Duration 812 ms by bot id=6523255231
2024-02-12 10:31:17,974 INFO Update id=774151700 is not handled. Duration 1 ms by bot id=6523255231
2024-02-12 10:31:17,974 ERROR Cause exception while process update id=774151700 by bot id=6523255231
FileNotFoundError: [Errno 2] No such file or directory: '/home/user/smscenter/sms/sent/9284728672-uWRIGY.txt'
Traceback (most recent call last):
  File "/home/user/bot/lcbot/venv/lib/python3.11/site-packages/aiogram/dispatcher/dispatcher.py", line 308, in _process_update
    response = await self.feed_update(bot, update, **kwargs)
               ^^^^^^^^^^^^^^^^^^^^^^^^^^^^^^^^^^^^^^^^^^^^^
  File "/home/user/bot/lcbot/venv/lib/python3.11/site-packages/aiogram/dispatcher/dispatcher.py", line 157, in feed_update
    response = await self.update.wrap_outer_middleware(
               ^^^^^^^^^^^^^^^^^^^^^^^^^^^^^^^^^^^^^^^^
  File "/home/user/bot/lcbot/venv/lib/python3.11/site-packages/aiogram/dispatcher/middlewares/error.py", line 25, in __call__
    return await handler(event, data)
           ^^^^^^^^^^^^^^^^^^^^^^^^^^
  File "/home/user/bot/lcbot/venv/lib/python3.11/site-packages/aiogram/dispatcher/middlewares/user_context.py", line 27, in __call__
    return await handler(event, data)
           ^^^^^^^^^^^^^^^^^^^^^^^^^^
  File "/home/user/bot/lcbot/venv/lib/python3.11/site-packages/aiogram/fsm/middleware.py", line 41, in __call__
    return await handler(event, data)
           ^^^^^^^^^^^^^^^^^^^^^^^^^^
  File "/home/user/bot/lcbot/venv/lib/python3.11/site-packages/aiogram/dispatcher/event/telegram.py", line 120, in trigger
    return await wrapped_inner(event, kwargs)
           ^^^^^^^^^^^^^^^^^^^^^^^^^^^^^^^^^^
  File "/home/user/bot/lcbot/venv/lib/python3.11/site-packages/aiogram/dispatcher/event/handler.py", line 42, in call
    return await wrapped()
           ^^^^^^^^^^^^^^^
  File "/home/user/bot/lcbot/venv/lib/python3.11/site-packages/aiogram/dispatcher/dispatcher.py", line 275, in _listen_update
    return await self.propagate_event(update_type=update_type, event=event, **kwargs)
           ^^^^^^^^^^^^^^^^^^^^^^^^^^^^^^^^^^^^^^^^^^^^^^^^^^^^^^^^^^^^^^^^^^^^^^^^^^
  File "/home/user/bot/lcbot/venv/lib/python3.11/site-packages/aiogram/dispatcher/router.py", line 116, in propagate_event
    return await observer.wrap_outer_middleware(_wrapped, event=event, data=kwargs)
           ^^^^^^^^^^^^^^^^^^^^^^^^^^^^^^^^^^^^^^^^^^^^^^^^^^^^^^^^^^^^^^^^^^^^^^^^
  File "/home/user/bot/lcbot/venv/lib/python3.11/site-packages/aiogram/dispatcher/router.py", line 111, in _wrapped
    return await self._propagate_event(
           ^^^^^^^^^^^^^^^^^^^^^^^^^^^^
  File "/home/user/bot/lcbot/venv/lib/python3.11/site-packages/aiogram/dispatcher/router.py", line 136, in _propagate_event
    response = await observer.trigger(event, **kwargs)
               ^^^^^^^^^^^^^^^^^^^^^^^^^^^^^^^^^^^^^^^
  File "/home/user/bot/lcbot/venv/lib/python3.11/site-packages/aiogram/dispatcher/event/telegram.py", line 120, in trigger
    return await wrapped_inner(event, kwargs)
           ^^^^^^^^^^^^^^^^^^^^^^^^^^^^^^^^^^
  File "/home/user/bot/lcbot/venv/lib/python3.11/site-packages/aiogram/dispatcher/event/handler.py", line 42, in call
    return await wrapped()
           ^^^^^^^^^^^^^^^
  File "/home/user/bot/lcbot/bot.py", line 269, in update_modem_ping_status
    message_id = await loop.run_in_executor(None, smscenter.get_message_id, filename)
                 ^^^^^^^^^^^^^^^^^^^^^^^^^^^^^^^^^^^^^^^^^^^^^^^^^^^^^^^^^^^^^^^^^^^^
  File "/usr/lib/python3.11/concurrent/futures/thread.py", line 58, in run
    result = self.fn(*self.args, **self.kwargs)
             ^^^^^^^^^^^^^^^^^^^^^^^^^^^^^^^^^^
  File "/home/user/bot/lcbot/smscenter.py", line 20, in get_message_id
    with open(file_check_id_name, "r", encoding="utf-8") as file:
         ^^^^^^^^^^^^^^^^^^^^^^^^^^^^^^^^^^^^^^^^^^^^^^^
FileNotFoundError: [Errno 2] No such file or directory: '/home/user/smscenter/sms/sent/9284728672-uWRIGY.txt'
2024-02-12 10:31:40,288 INFO Update id=774151701 is handled. Duration 303 ms by bot id=6523255231
2024-02-12 10:31:50,303 INFO Update id=774151702 is handled. Duration 151 ms by bot id=6523255231
2024-02-12 11:54:21,416 INFO Update id=774151703 is handled. Duration 878 ms by bot id=6523255231
2024-02-12 11:54:23,124 INFO Update id=774151704 is handled. Duration 357 ms by bot id=6523255231
2024-02-12 12:02:00,397 INFO Update id=774151705 is handled. Duration 394 ms by bot id=6523255231
2024-02-12 12:02:01,864 INFO Update id=774151706 is handled. Duration 231 ms by bot id=6523255231
2024-02-12 12:02:03,085 INFO Update id=774151707 is handled. Duration 208 ms by bot id=6523255231
2024-02-12 12:25:09,405 INFO Update id=774151708 is handled. Duration 1108 ms by bot id=6523255231
2024-02-12 12:25:15,506 INFO Update id=774151709 is handled. Duration 1260 ms by bot id=6523255231
2024-02-12 12:25:45,105 INFO Update id=774151710 is handled. Duration 266 ms by bot id=6523255231
2024-02-12 12:40:51,151 INFO Update id=774151711 is handled. Duration 797 ms by bot id=6523255231
2024-02-12 12:40:53,450 INFO Update id=774151712 is handled. Duration 370 ms by bot id=6523255231
2024-02-12 12:40:54,785 INFO Update id=774151713 is not handled. Duration 0 ms by bot id=6523255231
2024-02-12 12:40:54,786 ERROR Cause exception while process update id=774151713 by bot id=6523255231
FileNotFoundError: [Errno 2] No such file or directory: '/home/user/smscenter/sms/sent/9898267167-kAdfsI.txt'
Traceback (most recent call last):
  File "/home/user/bot/lcbot/venv/lib/python3.11/site-packages/aiogram/dispatcher/dispatcher.py", line 308, in _process_update
    response = await self.feed_update(bot, update, **kwargs)
               ^^^^^^^^^^^^^^^^^^^^^^^^^^^^^^^^^^^^^^^^^^^^^
  File "/home/user/bot/lcbot/venv/lib/python3.11/site-packages/aiogram/dispatcher/dispatcher.py", line 157, in feed_update
    response = await self.update.wrap_outer_middleware(
               ^^^^^^^^^^^^^^^^^^^^^^^^^^^^^^^^^^^^^^^^
  File "/home/user/bot/lcbot/venv/lib/python3.11/site-packages/aiogram/dispatcher/middlewares/error.py", line 25, in __call__
    return await handler(event, data)
           ^^^^^^^^^^^^^^^^^^^^^^^^^^
  File "/home/user/bot/lcbot/venv/lib/python3.11/site-packages/aiogram/dispatcher/middlewares/user_context.py", line 27, in __call__
    return await handler(event, data)
           ^^^^^^^^^^^^^^^^^^^^^^^^^^
  File "/home/user/bot/lcbot/venv/lib/python3.11/site-packages/aiogram/fsm/middleware.py", line 41, in __call__
    return await handler(event, data)
           ^^^^^^^^^^^^^^^^^^^^^^^^^^
  File "/home/user/bot/lcbot/venv/lib/python3.11/site-packages/aiogram/dispatcher/event/telegram.py", line 120, in trigger
    return await wrapped_inner(event, kwargs)
           ^^^^^^^^^^^^^^^^^^^^^^^^^^^^^^^^^^
  File "/home/user/bot/lcbot/venv/lib/python3.11/site-packages/aiogram/dispatcher/event/handler.py", line 42, in call
    return await wrapped()
           ^^^^^^^^^^^^^^^
  File "/home/user/bot/lcbot/venv/lib/python3.11/site-packages/aiogram/dispatcher/dispatcher.py", line 275, in _listen_update
    return await self.propagate_event(update_type=update_type, event=event, **kwargs)
           ^^^^^^^^^^^^^^^^^^^^^^^^^^^^^^^^^^^^^^^^^^^^^^^^^^^^^^^^^^^^^^^^^^^^^^^^^^
  File "/home/user/bot/lcbot/venv/lib/python3.11/site-packages/aiogram/dispatcher/router.py", line 116, in propagate_event
    return await observer.wrap_outer_middleware(_wrapped, event=event, data=kwargs)
           ^^^^^^^^^^^^^^^^^^^^^^^^^^^^^^^^^^^^^^^^^^^^^^^^^^^^^^^^^^^^^^^^^^^^^^^^
  File "/home/user/bot/lcbot/venv/lib/python3.11/site-packages/aiogram/dispatcher/router.py", line 111, in _wrapped
    return await self._propagate_event(
           ^^^^^^^^^^^^^^^^^^^^^^^^^^^^
  File "/home/user/bot/lcbot/venv/lib/python3.11/site-packages/aiogram/dispatcher/router.py", line 136, in _propagate_event
    response = await observer.trigger(event, **kwargs)
               ^^^^^^^^^^^^^^^^^^^^^^^^^^^^^^^^^^^^^^^
  File "/home/user/bot/lcbot/venv/lib/python3.11/site-packages/aiogram/dispatcher/event/telegram.py", line 120, in trigger
    return await wrapped_inner(event, kwargs)
           ^^^^^^^^^^^^^^^^^^^^^^^^^^^^^^^^^^
  File "/home/user/bot/lcbot/venv/lib/python3.11/site-packages/aiogram/dispatcher/event/handler.py", line 42, in call
    return await wrapped()
           ^^^^^^^^^^^^^^^
  File "/home/user/bot/lcbot/bot.py", line 269, in update_modem_ping_status
    message_id = await loop.run_in_executor(None, smscenter.get_message_id, filename)
                 ^^^^^^^^^^^^^^^^^^^^^^^^^^^^^^^^^^^^^^^^^^^^^^^^^^^^^^^^^^^^^^^^^^^^
  File "/usr/lib/python3.11/concurrent/futures/thread.py", line 58, in run
    result = self.fn(*self.args, **self.kwargs)
             ^^^^^^^^^^^^^^^^^^^^^^^^^^^^^^^^^^
  File "/home/user/bot/lcbot/smscenter.py", line 20, in get_message_id
    with open(file_check_id_name, "r", encoding="utf-8") as file:
         ^^^^^^^^^^^^^^^^^^^^^^^^^^^^^^^^^^^^^^^^^^^^^^^
FileNotFoundError: [Errno 2] No such file or directory: '/home/user/smscenter/sms/sent/9898267167-kAdfsI.txt'
2024-02-12 12:41:04,067 INFO Update id=774151714 is handled. Duration 110 ms by bot id=6523255231
2024-02-12 12:41:05,368 INFO Update id=774151715 is handled. Duration 115 ms by bot id=6523255231
2024-02-12 12:41:06,329 INFO Update id=774151716 is handled. Duration 119 ms by bot id=6523255231
2024-02-12 12:41:07,296 INFO Update id=774151717 is handled. Duration 141 ms by bot id=6523255231
2024-02-12 12:41:08,219 INFO Update id=774151718 is handled. Duration 116 ms by bot id=6523255231
2024-02-12 12:41:10,702 INFO Update id=774151719 is handled. Duration 174 ms by bot id=6523255231
2024-02-12 12:48:46,619 INFO Update id=774151720 is handled. Duration 339 ms by bot id=6523255231
2024-02-12 13:06:49,961 INFO Update id=774151721 is handled. Duration 770 ms by bot id=6523255231
2024-02-12 13:06:52,300 INFO Update id=774151722 is handled. Duration 341 ms by bot id=6523255231
2024-02-12 13:06:53,770 INFO Update id=774151723 is not handled. Duration 0 ms by bot id=6523255231
2024-02-12 13:06:53,770 ERROR Cause exception while process update id=774151723 by bot id=6523255231
FileNotFoundError: [Errno 2] No such file or directory: '/home/user/smscenter/sms/sent/9898267167-ev2VBW.txt'
Traceback (most recent call last):
  File "/home/user/bot/lcbot/venv/lib/python3.11/site-packages/aiogram/dispatcher/dispatcher.py", line 308, in _process_update
    response = await self.feed_update(bot, update, **kwargs)
               ^^^^^^^^^^^^^^^^^^^^^^^^^^^^^^^^^^^^^^^^^^^^^
  File "/home/user/bot/lcbot/venv/lib/python3.11/site-packages/aiogram/dispatcher/dispatcher.py", line 157, in feed_update
    response = await self.update.wrap_outer_middleware(
               ^^^^^^^^^^^^^^^^^^^^^^^^^^^^^^^^^^^^^^^^
  File "/home/user/bot/lcbot/venv/lib/python3.11/site-packages/aiogram/dispatcher/middlewares/error.py", line 25, in __call__
    return await handler(event, data)
           ^^^^^^^^^^^^^^^^^^^^^^^^^^
  File "/home/user/bot/lcbot/venv/lib/python3.11/site-packages/aiogram/dispatcher/middlewares/user_context.py", line 27, in __call__
    return await handler(event, data)
           ^^^^^^^^^^^^^^^^^^^^^^^^^^
  File "/home/user/bot/lcbot/venv/lib/python3.11/site-packages/aiogram/fsm/middleware.py", line 41, in __call__
    return await handler(event, data)
           ^^^^^^^^^^^^^^^^^^^^^^^^^^
  File "/home/user/bot/lcbot/venv/lib/python3.11/site-packages/aiogram/dispatcher/event/telegram.py", line 120, in trigger
    return await wrapped_inner(event, kwargs)
           ^^^^^^^^^^^^^^^^^^^^^^^^^^^^^^^^^^
  File "/home/user/bot/lcbot/venv/lib/python3.11/site-packages/aiogram/dispatcher/event/handler.py", line 42, in call
    return await wrapped()
           ^^^^^^^^^^^^^^^
  File "/home/user/bot/lcbot/venv/lib/python3.11/site-packages/aiogram/dispatcher/dispatcher.py", line 275, in _listen_update
    return await self.propagate_event(update_type=update_type, event=event, **kwargs)
           ^^^^^^^^^^^^^^^^^^^^^^^^^^^^^^^^^^^^^^^^^^^^^^^^^^^^^^^^^^^^^^^^^^^^^^^^^^
  File "/home/user/bot/lcbot/venv/lib/python3.11/site-packages/aiogram/dispatcher/router.py", line 116, in propagate_event
    return await observer.wrap_outer_middleware(_wrapped, event=event, data=kwargs)
           ^^^^^^^^^^^^^^^^^^^^^^^^^^^^^^^^^^^^^^^^^^^^^^^^^^^^^^^^^^^^^^^^^^^^^^^^
  File "/home/user/bot/lcbot/venv/lib/python3.11/site-packages/aiogram/dispatcher/router.py", line 111, in _wrapped
    return await self._propagate_event(
           ^^^^^^^^^^^^^^^^^^^^^^^^^^^^
  File "/home/user/bot/lcbot/venv/lib/python3.11/site-packages/aiogram/dispatcher/router.py", line 136, in _propagate_event
    response = await observer.trigger(event, **kwargs)
               ^^^^^^^^^^^^^^^^^^^^^^^^^^^^^^^^^^^^^^^
  File "/home/user/bot/lcbot/venv/lib/python3.11/site-packages/aiogram/dispatcher/event/telegram.py", line 120, in trigger
    return await wrapped_inner(event, kwargs)
           ^^^^^^^^^^^^^^^^^^^^^^^^^^^^^^^^^^
  File "/home/user/bot/lcbot/venv/lib/python3.11/site-packages/aiogram/dispatcher/event/handler.py", line 42, in call
    return await wrapped()
           ^^^^^^^^^^^^^^^
  File "/home/user/bot/lcbot/bot.py", line 269, in update_modem_ping_status
    message_id = await loop.run_in_executor(None, smscenter.get_message_id, filename)
                 ^^^^^^^^^^^^^^^^^^^^^^^^^^^^^^^^^^^^^^^^^^^^^^^^^^^^^^^^^^^^^^^^^^^^
  File "/usr/lib/python3.11/concurrent/futures/thread.py", line 58, in run
    result = self.fn(*self.args, **self.kwargs)
             ^^^^^^^^^^^^^^^^^^^^^^^^^^^^^^^^^^
  File "/home/user/bot/lcbot/smscenter.py", line 20, in get_message_id
    with open(file_check_id_name, "r", encoding="utf-8") as file:
         ^^^^^^^^^^^^^^^^^^^^^^^^^^^^^^^^^^^^^^^^^^^^^^^
FileNotFoundError: [Errno 2] No such file or directory: '/home/user/smscenter/sms/sent/9898267167-ev2VBW.txt'
2024-02-12 13:07:06,674 INFO Update id=774151724 is handled. Duration 230 ms by bot id=6523255231
2024-02-12 13:07:25,029 INFO Update id=774151725 is handled. Duration 258 ms by bot id=6523255231
2024-02-12 13:41:05,691 INFO Update id=774151726 is handled. Duration 487 ms by bot id=6523255231
2024-02-12 13:41:10,696 INFO Update id=774151727 is handled. Duration 515 ms by bot id=6523255231
2024-02-12 13:41:12,393 INFO Update id=774151728 is handled. Duration 466 ms by bot id=6523255231
2024-02-12 13:41:13,969 INFO Update id=774151729 is not handled. Duration 0 ms by bot id=6523255231
2024-02-12 13:41:13,969 ERROR Cause exception while process update id=774151729 by bot id=6523255231
FileNotFoundError: [Errno 2] No such file or directory: '/home/user/smscenter/sms/sent/9898267167-Do3M1L.txt'
Traceback (most recent call last):
  File "/home/user/bot/lcbot/venv/lib/python3.11/site-packages/aiogram/dispatcher/dispatcher.py", line 308, in _process_update
    response = await self.feed_update(bot, update, **kwargs)
               ^^^^^^^^^^^^^^^^^^^^^^^^^^^^^^^^^^^^^^^^^^^^^
  File "/home/user/bot/lcbot/venv/lib/python3.11/site-packages/aiogram/dispatcher/dispatcher.py", line 157, in feed_update
    response = await self.update.wrap_outer_middleware(
               ^^^^^^^^^^^^^^^^^^^^^^^^^^^^^^^^^^^^^^^^
  File "/home/user/bot/lcbot/venv/lib/python3.11/site-packages/aiogram/dispatcher/middlewares/error.py", line 25, in __call__
    return await handler(event, data)
           ^^^^^^^^^^^^^^^^^^^^^^^^^^
  File "/home/user/bot/lcbot/venv/lib/python3.11/site-packages/aiogram/dispatcher/middlewares/user_context.py", line 27, in __call__
    return await handler(event, data)
           ^^^^^^^^^^^^^^^^^^^^^^^^^^
  File "/home/user/bot/lcbot/venv/lib/python3.11/site-packages/aiogram/fsm/middleware.py", line 41, in __call__
    return await handler(event, data)
           ^^^^^^^^^^^^^^^^^^^^^^^^^^
  File "/home/user/bot/lcbot/venv/lib/python3.11/site-packages/aiogram/dispatcher/event/telegram.py", line 120, in trigger
    return await wrapped_inner(event, kwargs)
           ^^^^^^^^^^^^^^^^^^^^^^^^^^^^^^^^^^
  File "/home/user/bot/lcbot/venv/lib/python3.11/site-packages/aiogram/dispatcher/event/handler.py", line 42, in call
    return await wrapped()
           ^^^^^^^^^^^^^^^
  File "/home/user/bot/lcbot/venv/lib/python3.11/site-packages/aiogram/dispatcher/dispatcher.py", line 275, in _listen_update
    return await self.propagate_event(update_type=update_type, event=event, **kwargs)
           ^^^^^^^^^^^^^^^^^^^^^^^^^^^^^^^^^^^^^^^^^^^^^^^^^^^^^^^^^^^^^^^^^^^^^^^^^^
  File "/home/user/bot/lcbot/venv/lib/python3.11/site-packages/aiogram/dispatcher/router.py", line 116, in propagate_event
    return await observer.wrap_outer_middleware(_wrapped, event=event, data=kwargs)
           ^^^^^^^^^^^^^^^^^^^^^^^^^^^^^^^^^^^^^^^^^^^^^^^^^^^^^^^^^^^^^^^^^^^^^^^^
  File "/home/user/bot/lcbot/venv/lib/python3.11/site-packages/aiogram/dispatcher/router.py", line 111, in _wrapped
    return await self._propagate_event(
           ^^^^^^^^^^^^^^^^^^^^^^^^^^^^
  File "/home/user/bot/lcbot/venv/lib/python3.11/site-packages/aiogram/dispatcher/router.py", line 136, in _propagate_event
    response = await observer.trigger(event, **kwargs)
               ^^^^^^^^^^^^^^^^^^^^^^^^^^^^^^^^^^^^^^^
  File "/home/user/bot/lcbot/venv/lib/python3.11/site-packages/aiogram/dispatcher/event/telegram.py", line 120, in trigger
    return await wrapped_inner(event, kwargs)
           ^^^^^^^^^^^^^^^^^^^^^^^^^^^^^^^^^^
  File "/home/user/bot/lcbot/venv/lib/python3.11/site-packages/aiogram/dispatcher/event/handler.py", line 42, in call
    return await wrapped()
           ^^^^^^^^^^^^^^^
  File "/home/user/bot/lcbot/bot.py", line 269, in update_modem_ping_status
    message_id = await loop.run_in_executor(None, smscenter.get_message_id, filename)
                 ^^^^^^^^^^^^^^^^^^^^^^^^^^^^^^^^^^^^^^^^^^^^^^^^^^^^^^^^^^^^^^^^^^^^
  File "/usr/lib/python3.11/concurrent/futures/thread.py", line 58, in run
    result = self.fn(*self.args, **self.kwargs)
             ^^^^^^^^^^^^^^^^^^^^^^^^^^^^^^^^^^
  File "/home/user/bot/lcbot/smscenter.py", line 20, in get_message_id
    with open(file_check_id_name, "r", encoding="utf-8") as file:
         ^^^^^^^^^^^^^^^^^^^^^^^^^^^^^^^^^^^^^^^^^^^^^^^
FileNotFoundError: [Errno 2] No such file or directory: '/home/user/smscenter/sms/sent/9898267167-Do3M1L.txt'
2024-02-12 13:41:19,336 INFO Update id=774151730 is not handled. Duration 0 ms by bot id=6523255231
2024-02-12 13:41:19,336 ERROR Cause exception while process update id=774151730 by bot id=6523255231
FileNotFoundError: [Errno 2] No such file or directory: '/home/user/smscenter/sms/sent/9898267167-Do3M1L.txt'
Traceback (most recent call last):
  File "/home/user/bot/lcbot/venv/lib/python3.11/site-packages/aiogram/dispatcher/dispatcher.py", line 308, in _process_update
    response = await self.feed_update(bot, update, **kwargs)
               ^^^^^^^^^^^^^^^^^^^^^^^^^^^^^^^^^^^^^^^^^^^^^
  File "/home/user/bot/lcbot/venv/lib/python3.11/site-packages/aiogram/dispatcher/dispatcher.py", line 157, in feed_update
    response = await self.update.wrap_outer_middleware(
               ^^^^^^^^^^^^^^^^^^^^^^^^^^^^^^^^^^^^^^^^
  File "/home/user/bot/lcbot/venv/lib/python3.11/site-packages/aiogram/dispatcher/middlewares/error.py", line 25, in __call__
    return await handler(event, data)
           ^^^^^^^^^^^^^^^^^^^^^^^^^^
  File "/home/user/bot/lcbot/venv/lib/python3.11/site-packages/aiogram/dispatcher/middlewares/user_context.py", line 27, in __call__
    return await handler(event, data)
           ^^^^^^^^^^^^^^^^^^^^^^^^^^
  File "/home/user/bot/lcbot/venv/lib/python3.11/site-packages/aiogram/fsm/middleware.py", line 41, in __call__
    return await handler(event, data)
           ^^^^^^^^^^^^^^^^^^^^^^^^^^
  File "/home/user/bot/lcbot/venv/lib/python3.11/site-packages/aiogram/dispatcher/event/telegram.py", line 120, in trigger
    return await wrapped_inner(event, kwargs)
           ^^^^^^^^^^^^^^^^^^^^^^^^^^^^^^^^^^
  File "/home/user/bot/lcbot/venv/lib/python3.11/site-packages/aiogram/dispatcher/event/handler.py", line 42, in call
    return await wrapped()
           ^^^^^^^^^^^^^^^
  File "/home/user/bot/lcbot/venv/lib/python3.11/site-packages/aiogram/dispatcher/dispatcher.py", line 275, in _listen_update
    return await self.propagate_event(update_type=update_type, event=event, **kwargs)
           ^^^^^^^^^^^^^^^^^^^^^^^^^^^^^^^^^^^^^^^^^^^^^^^^^^^^^^^^^^^^^^^^^^^^^^^^^^
  File "/home/user/bot/lcbot/venv/lib/python3.11/site-packages/aiogram/dispatcher/router.py", line 116, in propagate_event
    return await observer.wrap_outer_middleware(_wrapped, event=event, data=kwargs)
           ^^^^^^^^^^^^^^^^^^^^^^^^^^^^^^^^^^^^^^^^^^^^^^^^^^^^^^^^^^^^^^^^^^^^^^^^
  File "/home/user/bot/lcbot/venv/lib/python3.11/site-packages/aiogram/dispatcher/router.py", line 111, in _wrapped
    return await self._propagate_event(
           ^^^^^^^^^^^^^^^^^^^^^^^^^^^^
  File "/home/user/bot/lcbot/venv/lib/python3.11/site-packages/aiogram/dispatcher/router.py", line 136, in _propagate_event
    response = await observer.trigger(event, **kwargs)
               ^^^^^^^^^^^^^^^^^^^^^^^^^^^^^^^^^^^^^^^
  File "/home/user/bot/lcbot/venv/lib/python3.11/site-packages/aiogram/dispatcher/event/telegram.py", line 120, in trigger
    return await wrapped_inner(event, kwargs)
           ^^^^^^^^^^^^^^^^^^^^^^^^^^^^^^^^^^
  File "/home/user/bot/lcbot/venv/lib/python3.11/site-packages/aiogram/dispatcher/event/handler.py", line 42, in call
    return await wrapped()
           ^^^^^^^^^^^^^^^
  File "/home/user/bot/lcbot/bot.py", line 269, in update_modem_ping_status
    message_id = await loop.run_in_executor(None, smscenter.get_message_id, filename)
                 ^^^^^^^^^^^^^^^^^^^^^^^^^^^^^^^^^^^^^^^^^^^^^^^^^^^^^^^^^^^^^^^^^^^^
  File "/usr/lib/python3.11/concurrent/futures/thread.py", line 58, in run
    result = self.fn(*self.args, **self.kwargs)
             ^^^^^^^^^^^^^^^^^^^^^^^^^^^^^^^^^^
  File "/home/user/bot/lcbot/smscenter.py", line 20, in get_message_id
    with open(file_check_id_name, "r", encoding="utf-8") as file:
         ^^^^^^^^^^^^^^^^^^^^^^^^^^^^^^^^^^^^^^^^^^^^^^^
FileNotFoundError: [Errno 2] No such file or directory: '/home/user/smscenter/sms/sent/9898267167-Do3M1L.txt'
2024-02-12 13:41:24,384 INFO Update id=774151731 is handled. Duration 121 ms by bot id=6523255231
2024-02-12 13:41:25,497 INFO Update id=774151732 is handled. Duration 137 ms by bot id=6523255231
2024-02-12 13:41:26,472 INFO Update id=774151733 is handled. Duration 140 ms by bot id=6523255231
2024-02-12 13:41:27,414 INFO Update id=774151734 is handled. Duration 114 ms by bot id=6523255231
2024-02-12 13:41:28,366 INFO Update id=774151735 is handled. Duration 121 ms by bot id=6523255231
2024-02-12 13:41:29,236 INFO Update id=774151736 is handled. Duration 131 ms by bot id=6523255231
2024-02-12 13:41:31,078 INFO Update id=774151737 is handled. Duration 112 ms by bot id=6523255231
2024-02-12 13:41:32,270 INFO Update id=774151738 is handled. Duration 109 ms by bot id=6523255231
2024-02-12 13:41:44,197 INFO Update id=774151739 is handled. Duration 135 ms by bot id=6523255231
2024-02-12 13:56:20,087 INFO Update id=774151740 is handled. Duration 358 ms by bot id=6523255231
2024-02-12 13:56:37,546 INFO Update id=774151741 is handled. Duration 1454 ms by bot id=6523255231
2024-02-12 13:56:39,445 INFO Update id=774151742 is handled. Duration 373 ms by bot id=6523255231
2024-02-12 14:53:38,351 INFO Update id=774151743 is handled. Duration 350 ms by bot id=6523255231
2024-02-12 14:53:38,379 INFO Update id=774151744 is handled. Duration 295 ms by bot id=6523255231
2024-02-12 14:53:38,412 INFO Update id=774151745 is handled. Duration 327 ms by bot id=6523255231
2024-02-12 14:53:43,559 INFO Update id=774151746 is handled. Duration 483 ms by bot id=6523255231
2024-02-12 14:53:45,142 INFO Update id=774151747 is handled. Duration 411 ms by bot id=6523255231
2024-02-12 14:53:46,058 INFO Update id=774151748 is not handled. Duration 0 ms by bot id=6523255231
2024-02-12 14:53:46,059 ERROR Cause exception while process update id=774151748 by bot id=6523255231
FileNotFoundError: [Errno 2] No such file or directory: '/home/user/smscenter/sms/sent/9898267167-AqQ0xw.txt'
Traceback (most recent call last):
  File "/home/user/bot/lcbot/venv/lib/python3.11/site-packages/aiogram/dispatcher/dispatcher.py", line 308, in _process_update
    response = await self.feed_update(bot, update, **kwargs)
               ^^^^^^^^^^^^^^^^^^^^^^^^^^^^^^^^^^^^^^^^^^^^^
  File "/home/user/bot/lcbot/venv/lib/python3.11/site-packages/aiogram/dispatcher/dispatcher.py", line 157, in feed_update
    response = await self.update.wrap_outer_middleware(
               ^^^^^^^^^^^^^^^^^^^^^^^^^^^^^^^^^^^^^^^^
  File "/home/user/bot/lcbot/venv/lib/python3.11/site-packages/aiogram/dispatcher/middlewares/error.py", line 25, in __call__
    return await handler(event, data)
           ^^^^^^^^^^^^^^^^^^^^^^^^^^
  File "/home/user/bot/lcbot/venv/lib/python3.11/site-packages/aiogram/dispatcher/middlewares/user_context.py", line 27, in __call__
    return await handler(event, data)
           ^^^^^^^^^^^^^^^^^^^^^^^^^^
  File "/home/user/bot/lcbot/venv/lib/python3.11/site-packages/aiogram/fsm/middleware.py", line 41, in __call__
    return await handler(event, data)
           ^^^^^^^^^^^^^^^^^^^^^^^^^^
  File "/home/user/bot/lcbot/venv/lib/python3.11/site-packages/aiogram/dispatcher/event/telegram.py", line 120, in trigger
    return await wrapped_inner(event, kwargs)
           ^^^^^^^^^^^^^^^^^^^^^^^^^^^^^^^^^^
  File "/home/user/bot/lcbot/venv/lib/python3.11/site-packages/aiogram/dispatcher/event/handler.py", line 42, in call
    return await wrapped()
           ^^^^^^^^^^^^^^^
  File "/home/user/bot/lcbot/venv/lib/python3.11/site-packages/aiogram/dispatcher/dispatcher.py", line 275, in _listen_update
    return await self.propagate_event(update_type=update_type, event=event, **kwargs)
           ^^^^^^^^^^^^^^^^^^^^^^^^^^^^^^^^^^^^^^^^^^^^^^^^^^^^^^^^^^^^^^^^^^^^^^^^^^
  File "/home/user/bot/lcbot/venv/lib/python3.11/site-packages/aiogram/dispatcher/router.py", line 116, in propagate_event
    return await observer.wrap_outer_middleware(_wrapped, event=event, data=kwargs)
           ^^^^^^^^^^^^^^^^^^^^^^^^^^^^^^^^^^^^^^^^^^^^^^^^^^^^^^^^^^^^^^^^^^^^^^^^
  File "/home/user/bot/lcbot/venv/lib/python3.11/site-packages/aiogram/dispatcher/router.py", line 111, in _wrapped
    return await self._propagate_event(
           ^^^^^^^^^^^^^^^^^^^^^^^^^^^^
  File "/home/user/bot/lcbot/venv/lib/python3.11/site-packages/aiogram/dispatcher/router.py", line 136, in _propagate_event
    response = await observer.trigger(event, **kwargs)
               ^^^^^^^^^^^^^^^^^^^^^^^^^^^^^^^^^^^^^^^
  File "/home/user/bot/lcbot/venv/lib/python3.11/site-packages/aiogram/dispatcher/event/telegram.py", line 120, in trigger
    return await wrapped_inner(event, kwargs)
           ^^^^^^^^^^^^^^^^^^^^^^^^^^^^^^^^^^
  File "/home/user/bot/lcbot/venv/lib/python3.11/site-packages/aiogram/dispatcher/event/handler.py", line 42, in call
    return await wrapped()
           ^^^^^^^^^^^^^^^
  File "/home/user/bot/lcbot/bot.py", line 269, in update_modem_ping_status
    message_id = await loop.run_in_executor(None, smscenter.get_message_id, filename)
                 ^^^^^^^^^^^^^^^^^^^^^^^^^^^^^^^^^^^^^^^^^^^^^^^^^^^^^^^^^^^^^^^^^^^^
  File "/usr/lib/python3.11/concurrent/futures/thread.py", line 58, in run
    result = self.fn(*self.args, **self.kwargs)
             ^^^^^^^^^^^^^^^^^^^^^^^^^^^^^^^^^^
  File "/home/user/bot/lcbot/smscenter.py", line 20, in get_message_id
    with open(file_check_id_name, "r", encoding="utf-8") as file:
         ^^^^^^^^^^^^^^^^^^^^^^^^^^^^^^^^^^^^^^^^^^^^^^^
FileNotFoundError: [Errno 2] No such file or directory: '/home/user/smscenter/sms/sent/9898267167-AqQ0xw.txt'
2024-02-12 14:54:11,026 INFO Update id=774151749 is handled. Duration 255 ms by bot id=6523255231
2024-02-12 15:01:45,865 INFO Update id=774151750 is handled. Duration 60705 ms by bot id=6523255231
2024-02-12 15:11:33,729 INFO Update id=774151751 is handled. Duration 61347 ms by bot id=6523255231
2024-02-12 15:12:45,063 INFO Update id=774151753 is handled. Duration 677 ms by bot id=6523255231
2024-02-12 15:13:07,538 INFO Update id=774151752 is handled. Duration 60622 ms by bot id=6523255231
2024-02-12 15:15:49,804 INFO Update id=774151754 is handled. Duration 1339 ms by bot id=6523255231
2024-02-12 15:34:49,483 INFO Update id=774151755 is handled. Duration 60643 ms by bot id=6523255231
2024-02-12 15:36:14,873 INFO Update id=774151756 is handled. Duration 61349 ms by bot id=6523255231
2024-02-12 15:47:13,735 INFO Update id=774151757 is handled. Duration 5476 ms by bot id=6523255231
2024-02-12 16:32:37,045 INFO Update id=774151758 is handled. Duration 60764 ms by bot id=6523255231
2024-02-12 16:33:02,799 INFO Update id=774151759 is handled. Duration 62425 ms by bot id=6523255231
2024-02-12 16:33:41,662 INFO Update id=774151760 is handled. Duration 828 ms by bot id=6523255231
2024-02-12 16:42:03,142 INFO Update id=774151761 is handled. Duration 3942 ms by bot id=6523255231
2024-02-12 17:07:50,257 INFO Update id=774151762 is handled. Duration 4593 ms by bot id=6523255231
2024-02-12 17:13:22,811 INFO Update id=774151763 is handled. Duration 818 ms by bot id=6523255231
2024-02-12 17:13:25,833 INFO Update id=774151764 is handled. Duration 1408 ms by bot id=6523255231
2024-02-12 17:13:27,203 INFO Update id=774151765 is not handled. Duration 1 ms by bot id=6523255231
2024-02-12 17:13:27,203 ERROR Cause exception while process update id=774151765 by bot id=6523255231
FileNotFoundError: [Errno 2] No such file or directory: '/home/user/smscenter/sms/sent/9898267167-8VebcS.txt'
Traceback (most recent call last):
  File "/home/user/bot/lcbot/venv/lib/python3.11/site-packages/aiogram/dispatcher/dispatcher.py", line 308, in _process_update
    response = await self.feed_update(bot, update, **kwargs)
               ^^^^^^^^^^^^^^^^^^^^^^^^^^^^^^^^^^^^^^^^^^^^^
  File "/home/user/bot/lcbot/venv/lib/python3.11/site-packages/aiogram/dispatcher/dispatcher.py", line 157, in feed_update
    response = await self.update.wrap_outer_middleware(
               ^^^^^^^^^^^^^^^^^^^^^^^^^^^^^^^^^^^^^^^^
  File "/home/user/bot/lcbot/venv/lib/python3.11/site-packages/aiogram/dispatcher/middlewares/error.py", line 25, in __call__
    return await handler(event, data)
           ^^^^^^^^^^^^^^^^^^^^^^^^^^
  File "/home/user/bot/lcbot/venv/lib/python3.11/site-packages/aiogram/dispatcher/middlewares/user_context.py", line 27, in __call__
    return await handler(event, data)
           ^^^^^^^^^^^^^^^^^^^^^^^^^^
  File "/home/user/bot/lcbot/venv/lib/python3.11/site-packages/aiogram/fsm/middleware.py", line 41, in __call__
    return await handler(event, data)
           ^^^^^^^^^^^^^^^^^^^^^^^^^^
  File "/home/user/bot/lcbot/venv/lib/python3.11/site-packages/aiogram/dispatcher/event/telegram.py", line 120, in trigger
    return await wrapped_inner(event, kwargs)
           ^^^^^^^^^^^^^^^^^^^^^^^^^^^^^^^^^^
  File "/home/user/bot/lcbot/venv/lib/python3.11/site-packages/aiogram/dispatcher/event/handler.py", line 42, in call
    return await wrapped()
           ^^^^^^^^^^^^^^^
  File "/home/user/bot/lcbot/venv/lib/python3.11/site-packages/aiogram/dispatcher/dispatcher.py", line 275, in _listen_update
    return await self.propagate_event(update_type=update_type, event=event, **kwargs)
           ^^^^^^^^^^^^^^^^^^^^^^^^^^^^^^^^^^^^^^^^^^^^^^^^^^^^^^^^^^^^^^^^^^^^^^^^^^
  File "/home/user/bot/lcbot/venv/lib/python3.11/site-packages/aiogram/dispatcher/router.py", line 116, in propagate_event
    return await observer.wrap_outer_middleware(_wrapped, event=event, data=kwargs)
           ^^^^^^^^^^^^^^^^^^^^^^^^^^^^^^^^^^^^^^^^^^^^^^^^^^^^^^^^^^^^^^^^^^^^^^^^
  File "/home/user/bot/lcbot/venv/lib/python3.11/site-packages/aiogram/dispatcher/router.py", line 111, in _wrapped
    return await self._propagate_event(
           ^^^^^^^^^^^^^^^^^^^^^^^^^^^^
  File "/home/user/bot/lcbot/venv/lib/python3.11/site-packages/aiogram/dispatcher/router.py", line 136, in _propagate_event
    response = await observer.trigger(event, **kwargs)
               ^^^^^^^^^^^^^^^^^^^^^^^^^^^^^^^^^^^^^^^
  File "/home/user/bot/lcbot/venv/lib/python3.11/site-packages/aiogram/dispatcher/event/telegram.py", line 120, in trigger
    return await wrapped_inner(event, kwargs)
           ^^^^^^^^^^^^^^^^^^^^^^^^^^^^^^^^^^
  File "/home/user/bot/lcbot/venv/lib/python3.11/site-packages/aiogram/dispatcher/event/handler.py", line 42, in call
    return await wrapped()
           ^^^^^^^^^^^^^^^
  File "/home/user/bot/lcbot/bot.py", line 269, in update_modem_ping_status
    message_id = await loop.run_in_executor(None, smscenter.get_message_id, filename)
                 ^^^^^^^^^^^^^^^^^^^^^^^^^^^^^^^^^^^^^^^^^^^^^^^^^^^^^^^^^^^^^^^^^^^^
  File "/usr/lib/python3.11/concurrent/futures/thread.py", line 58, in run
    result = self.fn(*self.args, **self.kwargs)
             ^^^^^^^^^^^^^^^^^^^^^^^^^^^^^^^^^^
  File "/home/user/bot/lcbot/smscenter.py", line 20, in get_message_id
    with open(file_check_id_name, "r", encoding="utf-8") as file:
         ^^^^^^^^^^^^^^^^^^^^^^^^^^^^^^^^^^^^^^^^^^^^^^^
FileNotFoundError: [Errno 2] No such file or directory: '/home/user/smscenter/sms/sent/9898267167-8VebcS.txt'
2024-02-12 17:13:32,981 INFO Update id=774151766 is not handled. Duration 1 ms by bot id=6523255231
2024-02-12 17:13:32,981 ERROR Cause exception while process update id=774151766 by bot id=6523255231
FileNotFoundError: [Errno 2] No such file or directory: '/home/user/smscenter/sms/sent/9898267167-8VebcS.txt'
Traceback (most recent call last):
  File "/home/user/bot/lcbot/venv/lib/python3.11/site-packages/aiogram/dispatcher/dispatcher.py", line 308, in _process_update
    response = await self.feed_update(bot, update, **kwargs)
               ^^^^^^^^^^^^^^^^^^^^^^^^^^^^^^^^^^^^^^^^^^^^^
  File "/home/user/bot/lcbot/venv/lib/python3.11/site-packages/aiogram/dispatcher/dispatcher.py", line 157, in feed_update
    response = await self.update.wrap_outer_middleware(
               ^^^^^^^^^^^^^^^^^^^^^^^^^^^^^^^^^^^^^^^^
  File "/home/user/bot/lcbot/venv/lib/python3.11/site-packages/aiogram/dispatcher/middlewares/error.py", line 25, in __call__
    return await handler(event, data)
           ^^^^^^^^^^^^^^^^^^^^^^^^^^
  File "/home/user/bot/lcbot/venv/lib/python3.11/site-packages/aiogram/dispatcher/middlewares/user_context.py", line 27, in __call__
    return await handler(event, data)
           ^^^^^^^^^^^^^^^^^^^^^^^^^^
  File "/home/user/bot/lcbot/venv/lib/python3.11/site-packages/aiogram/fsm/middleware.py", line 41, in __call__
    return await handler(event, data)
           ^^^^^^^^^^^^^^^^^^^^^^^^^^
  File "/home/user/bot/lcbot/venv/lib/python3.11/site-packages/aiogram/dispatcher/event/telegram.py", line 120, in trigger
    return await wrapped_inner(event, kwargs)
           ^^^^^^^^^^^^^^^^^^^^^^^^^^^^^^^^^^
  File "/home/user/bot/lcbot/venv/lib/python3.11/site-packages/aiogram/dispatcher/event/handler.py", line 42, in call
    return await wrapped()
           ^^^^^^^^^^^^^^^
  File "/home/user/bot/lcbot/venv/lib/python3.11/site-packages/aiogram/dispatcher/dispatcher.py", line 275, in _listen_update
    return await self.propagate_event(update_type=update_type, event=event, **kwargs)
           ^^^^^^^^^^^^^^^^^^^^^^^^^^^^^^^^^^^^^^^^^^^^^^^^^^^^^^^^^^^^^^^^^^^^^^^^^^
  File "/home/user/bot/lcbot/venv/lib/python3.11/site-packages/aiogram/dispatcher/router.py", line 116, in propagate_event
    return await observer.wrap_outer_middleware(_wrapped, event=event, data=kwargs)
           ^^^^^^^^^^^^^^^^^^^^^^^^^^^^^^^^^^^^^^^^^^^^^^^^^^^^^^^^^^^^^^^^^^^^^^^^
  File "/home/user/bot/lcbot/venv/lib/python3.11/site-packages/aiogram/dispatcher/router.py", line 111, in _wrapped
    return await self._propagate_event(
           ^^^^^^^^^^^^^^^^^^^^^^^^^^^^
  File "/home/user/bot/lcbot/venv/lib/python3.11/site-packages/aiogram/dispatcher/router.py", line 136, in _propagate_event
    response = await observer.trigger(event, **kwargs)
               ^^^^^^^^^^^^^^^^^^^^^^^^^^^^^^^^^^^^^^^
  File "/home/user/bot/lcbot/venv/lib/python3.11/site-packages/aiogram/dispatcher/event/telegram.py", line 120, in trigger
    return await wrapped_inner(event, kwargs)
           ^^^^^^^^^^^^^^^^^^^^^^^^^^^^^^^^^^
  File "/home/user/bot/lcbot/venv/lib/python3.11/site-packages/aiogram/dispatcher/event/handler.py", line 42, in call
    return await wrapped()
           ^^^^^^^^^^^^^^^
  File "/home/user/bot/lcbot/bot.py", line 269, in update_modem_ping_status
    message_id = await loop.run_in_executor(None, smscenter.get_message_id, filename)
                 ^^^^^^^^^^^^^^^^^^^^^^^^^^^^^^^^^^^^^^^^^^^^^^^^^^^^^^^^^^^^^^^^^^^^
  File "/usr/lib/python3.11/concurrent/futures/thread.py", line 58, in run
    result = self.fn(*self.args, **self.kwargs)
             ^^^^^^^^^^^^^^^^^^^^^^^^^^^^^^^^^^
  File "/home/user/bot/lcbot/smscenter.py", line 20, in get_message_id
    with open(file_check_id_name, "r", encoding="utf-8") as file:
         ^^^^^^^^^^^^^^^^^^^^^^^^^^^^^^^^^^^^^^^^^^^^^^^
FileNotFoundError: [Errno 2] No such file or directory: '/home/user/smscenter/sms/sent/9898267167-8VebcS.txt'
2024-02-12 17:13:34,746 INFO Update id=774151767 is handled. Duration 142 ms by bot id=6523255231
2024-02-12 17:13:36,126 INFO Update id=774151768 is handled. Duration 152 ms by bot id=6523255231
2024-02-12 17:13:37,293 INFO Update id=774151769 is handled. Duration 169 ms by bot id=6523255231
2024-02-12 17:13:38,427 INFO Update id=774151770 is handled. Duration 202 ms by bot id=6523255231
2024-02-12 17:13:39,675 INFO Update id=774151771 is handled. Duration 281 ms by bot id=6523255231
2024-02-12 17:13:40,902 INFO Update id=774151772 is handled. Duration 280 ms by bot id=6523255231
2024-02-12 17:13:42,057 INFO Update id=774151773 is handled. Duration 204 ms by bot id=6523255231
2024-02-12 17:13:43,185 INFO Update id=774151774 is handled. Duration 216 ms by bot id=6523255231
2024-02-12 17:13:44,198 INFO Update id=774151775 is handled. Duration 149 ms by bot id=6523255231
2024-02-12 17:13:45,157 INFO Update id=774151776 is handled. Duration 130 ms by bot id=6523255231
2024-02-12 17:13:46,081 INFO Update id=774151777 is handled. Duration 156 ms by bot id=6523255231
2024-02-12 17:13:54,404 INFO Update id=774151778 is handled. Duration 150 ms by bot id=6523255231
2024-02-12 18:06:59,976 INFO Update id=774151779 is handled. Duration 60807 ms by bot id=6523255231
2024-02-12 20:49:24,717 INFO Update id=774151780 is handled. Duration 732 ms by bot id=6523255231
2024-02-12 21:16:29,203 INFO Update id=774151781 is handled. Duration 853 ms by bot id=6523255231
2024-02-12 21:17:21,508 INFO Update id=774151782 is handled. Duration 720 ms by bot id=6523255231
2024-02-12 21:17:39,219 INFO Update id=774151783 is handled. Duration 1567 ms by bot id=6523255231
2024-02-12 21:18:09,970 INFO Update id=774151784 is handled. Duration 532 ms by bot id=6523255231
2024-02-13 04:02:03,183 ERROR Failed to fetch updates - TelegramNetworkError: HTTP Client says - ServerDisconnectedError: Server disconnected
2024-02-13 04:02:03,183 WARNING Sleep for 1.000000 seconds and try again... (tryings = 0, bot id = 6523255231)
2024-02-13 04:02:14,467 INFO Connection established (tryings = 1, bot id = 6523255231)
